<?xml version="1.0"?>
<robot xmlns:xacro="http://www.ros.org/wiki/xacro" name="straw_cluster2">

<xacro:arg name="tf_prefix" default=""/>

<!-- Robot1 -->
<link name="$(arg tf_prefix)/yball_stem4">
  <gravity>1</gravity>
  <inertial>
    <origin xyz="0 0 0" rpy="0 0 0"/>
    <mass value=".00001"/>
    <inertia ixx="0.00001" ixy="0.0" ixz="0.0" iyy="0.00001" iyz="0.0" izz="0.00001" />
  </inertial>
  <visual><geometry><sphere radius=".00001"/></geometry></visual>
  <collision><geometry><sphere radius=".00001"/></geometry></collision>
</link>
<gazebo reference="$(arg tf_prefix)/yball_stem4">
  <material>Gazebo/Green</material>
</gazebo>



<joint name="$(arg tf_prefix)/stem4y" type="revolute" >
  <parent link="/Plink1M" />
  <child link="$(arg tf_prefix)/yball_stem4" />
  <origin xyz="0.15 0.5 0.44" rpy="0 0 0"/> <!-- <origin xyz="0.15 0.06 1.19" rpy="0 0 0"/> in case of reference /base_link -->
  <axis xyz="0 1 0" />
  <dynamics damping="0.0001" friction="0.0002"/>
  <limit 
      lower="-${pi}" upper="${pi}"
      effort="1" velocity="0.1" />
</joint>
<!--<transmission name="tran_stem4y">
  <type>transmission_interface/SimpleTransmission</type>
  <joint name="$(arg tf_prefix)/stem4y">
    <hardwareInterface>hardware_interface/EffortJointInterface</hardwareInterface>
  </joint>
  <actuator name="$(arg tf_prefix)/act_stem4y">
    <hardwareInterface>hardware_interface/EffortJointInterface</hardwareInterface>
    <mechanicalReduction>1</mechanicalReduction>
  </actuator>
</transmission> -->


<link name="$(arg tf_prefix)/xball_stem4">
  <gravity>1</gravity>
  <inertial>
    <origin xyz="0 0 0" rpy="0 0 0"/>
    <mass value=".00001"/>
    <inertia ixx="0.0000004" ixy="0.0" ixz="0.0" iyy="0.0000004" iyz="0.0" izz="0.0000004" />
  </inertial>
  <visual><geometry><sphere radius=".00001"/></geometry></visual>
  <collision><geometry><sphere radius=".00001"/></geometry></collision>
</link>
<gazebo reference="$(arg tf_prefix)/xball_stem4">
  <material>Gazebo/Green</material>
</gazebo>


<joint name="$(arg tf_prefix)/stem4x" type="revolute" >
  <parent link="$(arg tf_prefix)/yball_stem4"/>
  <child link="$(arg tf_prefix)/xball_stem4"/>
  <origin xyz="0 0 0" rpy="0 0 0"/> 
  <axis xyz="1 0 0" />
  <dynamics damping="0.0001" friction="0.0002" />
  <limit 
      lower="-${pi}" upper="${pi}"
      effort="1" velocity="0.1" />
</joint>
<!--<transmission name="tran_stem4x">
  <type>transmission_interface/SimpleTransmission</type>
  <joint name="$(arg tf_prefix)/stem4x">
    <hardwareInterface>hardware_interface/EffortJointInterface</hardwareInterface>
  </joint>
  <actuator name="$(arg tf_prefix)/act_stem4x">
    <hardwareInterface>hardware_interface/EffortJointInterface</hardwareInterface>
    <mechanicalReduction>1</mechanicalReduction>
  </actuator>
</transmission> -->


<!-- Define stem of straw4 -->
<link name="$(arg tf_prefix)/stem4">
  <gravity>1</gravity>
  <inertial>
    <origin xyz="0 0 0" rpy="0 0 0"/>
    <mass value="0.001"/>
    <inertia
      ixx="0.0000000005" ixy="0.0" ixz="0.0"
      iyy="0.0000000005" iyz="0.0" 
      izz="0.0000000005"/>
  </inertial>
  <collision>
    <geometry>
		<cylinder length="0.15" radius="0.003"/>
    </geometry>
    <material name="green">
      <color rgba="0 ${128/255} 0 1"/>
    </material>
    <origin xyz="0 0 -0.075" rpy="0 0 0"/>
  </collision>
  <visual>
    <geometry>
		<cylinder length="0.15" radius="0.003"/>
    </geometry>
    <material name="green">
      <color rgba="0 ${128/255} 0 1"/>
    </material>
    <origin xyz="0 0 -0.075" rpy="0 0 0"/>
  </visual>
</link>
<gazebo reference="$(arg tf_prefix)/stem4">
  <mu1>0.01</mu1>
  <mu2>0.01</mu2>
  <selfCollide>true</selfCollide>
  <maxContacts>2</maxContacts>
  <minDepth>0</minDepth>
  <maxVel>0.01</maxVel>
  <kp  value="1" />
  <kd  value="0.1" /> 
  <material>Gazebo/Green</material>
</gazebo>


<joint name="$(arg tf_prefix)/xball_stem4" type="fixed">
  <parent link="$(arg tf_prefix)/xball_stem4"/>
  <child link="$(arg tf_prefix)/stem4"/>
  <origin xyz="0 0 0" rpy="0 0 0"/>  
</joint>

<!-- <joint name="$(arg tf_prefix)/tabletop28_stem4" type="revolute">
  <parent link="/base_link"/>
  <child link="$(arg tf_prefix)/stem4"/>
  <origin xyz="0.15 0.06 1.19" rpy="0 0 0"/>  
  <axis xyz="0 1 0" />
  <dynamics damping="10" friction="200" />
  <limit 
      lower="-${pi/2}" upper="${pi/2}"
      effort="10" velocity="0.1" />
</joint> 
<transmission name="tran_stem4">
  <type>transmission_interface/SimpleTransmission</type>
  <joint name="$(arg tf_prefix)/tabletop28_stem4">
    <hardwareInterface>hardware_interface/EffortJointInterface</hardwareInterface>
  </joint>
  <actuator name="$(arg tf_prefix)/act_stem4y">
    <hardwareInterface>hardware_interface/EffortJointInterface</hardwareInterface>
    <mechanicalReduction>1</mechanicalReduction>
  </actuator>
</transmission>  -->




<!-- Define straw4 -->
<link name="$(arg tf_prefix)/straw4">
  <gravity>1</gravity>
  <inertial>
    <origin xyz="0 0 0" rpy="0 0 0"/>
    <mass value="0.002"/>
    <inertia
      ixx="0.00000018" ixy="0.0" ixz="0.0"
      iyy="0.00000018" iyz="0.0" 
      izz="0.00000018"/>
  </inertial>
  <collision>
    <geometry>
    <sphere radius="0.015"/>
    </geometry>
  </collision>
  <visual>
    <geometry>
		<sphere radius="0.015"/>
    </geometry>
    <material name="Red">
      <color rgba="1 0 0 1"/>
    </material>
  </visual>
</link>
<gazebo reference="$(arg tf_prefix)/straw4">
  <mu1>0.01</mu1>
  <mu2>0.01</mu2>
  <selfCollide>true</selfCollide>
  <maxContacts>2</maxContacts>
  <minDepth>0</minDepth>
  <maxVel>0.01</maxVel>
  <kp  value="1" />
  <kd  value="0.1" /> 
  <material>Gazebo/Red</material>
</gazebo>


<joint name="$(arg tf_prefix)/straw4_stem4" type="fixed"> 
  <parent link="$(arg tf_prefix)/stem4"/>
  <child link="$(arg tf_prefix)/straw4"/>
  <origin xyz="0 0 -0.15" rpy="0 0 0"/> 
</joint> 


<!-- Robot2 -->
<link name="$(arg tf_prefix)/yball_stem5">
  <gravity>1</gravity>
  <inertial>
    <origin xyz="0 0 0" rpy="0 0 0"/>
    <mass value=".00001"/>
    <inertia ixx="0.0000004" ixy="0.0" ixz="0.0" iyy="0.0000004" iyz="0.0" izz="0.0000004" />
  </inertial>
  <visual><geometry><sphere radius=".00001"/></geometry></visual>
  <collision><geometry><sphere radius=".00001"/></geometry></collision>
</link>
<gazebo reference="$(arg tf_prefix)/yball_stem5">
  <material>Gazebo/Green</material>
</gazebo>



<joint name="$(arg tf_prefix)/stem5y" type="revolute" >
  <parent link="/Plink1M" />
  <child link="$(arg tf_prefix)/yball_stem5" />
  <origin xyz="0.12 0.5 0.44" rpy="0 0 0"/> <!-- <origin xyz="0.12 0.06 1.19" rpy="0 0 0"/> in case of reference /base_link -->
  <axis xyz="0 1 0" />
  <dynamics damping="0.0001" friction="0.0002"/>
  <limit 
      lower="-${pi}" upper="${pi}"
      effort="1" velocity="0.1" />
</joint>
<!--<transmission name="tran_stem5y">
  <type>transmission_interface/SimpleTransmission</type>
  <joint name="$(arg tf_prefix)/stem5y">
    <hardwareInterface>hardware_interface/EffortJointInterface</hardwareInterface>
  </joint>
  <actuator name="$(arg tf_prefix)/act_stem5y">
    <hardwareInterface>hardware_interface/EffortJointInterface</hardwareInterface>
    <mechanicalReduction>1</mechanicalReduction>
  </actuator>
</transmission> --> 


<link name="$(arg tf_prefix)/xball_stem5">
  <gravity>1</gravity>
  <inertial>
    <origin xyz="0 0 0" rpy="0 0 0"/>
    <mass value=".00001"/>
    <inertia ixx="0.0000004" ixy="0.0" ixz="0.0" iyy="0.0000004" iyz="0.0" izz="0.0000004" />
  </inertial>
  <visual><geometry><sphere radius=".00001"/></geometry></visual>
  <collision><geometry><sphere radius=".00001"/></geometry></collision>
</link>
<gazebo reference="$(arg tf_prefix)/xball_stem5">
  <material>Gazebo/Green</material>
</gazebo>


<joint name="$(arg tf_prefix)/stem5x" type="revolute" >
  <parent link="$(arg tf_prefix)/yball_stem5"/>
  <child link="$(arg tf_prefix)/xball_stem5"/>
  <origin xyz="0 0 0" rpy="0 0 0"/> 
  <axis xyz="1 0 0" />
  <dynamics damping="0.0001" friction="0.0002" />
  <limit 
      lower="-${pi}" upper="${pi}"
      effort="1" velocity="0.1" />
</joint>
<!--<transmission name="tran_stem5x">
  <type>transmission_interface/SimpleTransmission</type>
  <joint name="$(arg tf_prefix)/stem5x">
    <hardwareInterface>hardware_interface/EffortJointInterface</hardwareInterface>
  </joint>
  <actuator name="$(arg tf_prefix)/act_stem5x">
    <hardwareInterface>hardware_interface/EffortJointInterface</hardwareInterface>
    <mechanicalReduction>1</mechanicalReduction>
  </actuator>
</transmission> -->

<!-- Define stem of straw5 -->
<link name="$(arg tf_prefix)/stem5">
  <gravity>1</gravity>
  <inertial>
    <origin xyz="0 0 0" rpy="0 0 0"/>
    <mass value="0.001"/>
    <inertia
      ixx="0.0000000005" ixy="0.0" ixz="0.0"
      iyy="0.0000000005" iyz="0.0" 
      izz="0.0000000005"/>
  </inertial>
  <collision>
    <geometry>
		<cylinder length="0.15" radius="0.003"/>
    </geometry>
    <material name="green">
      <color rgba="0 ${128/255} 0 1"/>
    </material>
    <origin xyz="0 0 -0.075" rpy="0 0 0"/>
  </collision>
  <visual>
    <geometry>
		<cylinder length="0.15" radius="0.003"/>
    </geometry>
    <material name="green">
      <color rgba="0 ${128/255} 0 1"/>
    </material>
    <origin xyz="0 0 -0.075" rpy="0 0 0"/>
  </visual>
</link>
<gazebo reference="$(arg tf_prefix)/stem5">
  <mu1>0.01</mu1>
  <mu2>0.01</mu2>
  <selfCollide>true</selfCollide>
  <maxContacts>2</maxContacts>
  <minDepth>0</minDepth>
  <maxVel>0.01</maxVel>
  <kp  value="1" />
  <kd  value="0.1" /> 
  <material>Gazebo/Green</material>
</gazebo>


<joint name="$(arg tf_prefix)/xball_stem5" type="fixed">
  <parent link="$(arg tf_prefix)/xball_stem5"/>
  <child link="$(arg tf_prefix)/stem5"/>
  <origin xyz="0 0 0" rpy="0 0 0"/>  
</joint>

<!-- <joint name="$(arg tf_prefix)/tabletop28_stem5" type="revolute">
  <parent link="/base_link"/>
  <child link="$(arg tf_prefix)/stem5"/>
  <origin xyz="0.12 0.06 1.19" rpy="0 0 0"/>  
  <axis xyz="0 1 0" />
  <dynamics damping="10" friction="200" />
  <limit 
      lower="-${pi/2}" upper="${pi/2}"
      effort="10" velocity="0.1" />
</joint> 
<transmission name="tran_stem5">
  <type>transmission_interface/SimpleTransmission</type>
  <joint name="$(arg tf_prefix)/tabletop28_stem5">
    <hardwareInterface>hardware_interface/EffortJointInterface</hardwareInterface>
  </joint>
  <actuator name="$(arg tf_prefix)/act_stem5y">
    <hardwareInterface>hardware_interface/EffortJointInterface</hardwareInterface>
    <mechanicalReduction>1</mechanicalReduction>
  </actuator>
</transmission> --> 



<!-- Define straw5 -->
<link name="$(arg tf_prefix)/straw5">
  <gravity>1</gravity>
  <inertial>
    <origin xyz="0 0 0" rpy="0 0 0"/>
    <mass value="0.002"/>
    <inertia
      ixx="0.00000018" ixy="0.0" ixz="0.0"
      iyy="0.00000018" iyz="0.0" 
      izz="0.00000018"/>
  </inertial>
  <collision>
    <geometry>
    <sphere radius="0.015"/>
    </geometry>
  </collision>
  <visual>
    <geometry>
		<sphere radius="0.015"/>
    </geometry>
    <material name="Red">
      <color rgba="1 0 0 1"/>
    </material>
  </visual>
</link>
<gazebo reference="$(arg tf_prefix)/straw5">
  <mu1>0.01</mu1>
  <mu2>0.01</mu2>
  <selfCollide>true</selfCollide>
  <maxContacts>2</maxContacts>
  <minDepth>0</minDepth>
  <maxVel>0.01</maxVel>
  <kp  value="1" />
  <kd  value="0.1" /> 
  <material>Gazebo/Red</material>
</gazebo>


<joint name="$(arg tf_prefix)/straw5_stem5" type="fixed"> 
  <parent link="$(arg tf_prefix)/stem5"/>
  <child link="$(arg tf_prefix)/straw5"/>
  <origin xyz="0 0 -0.15" rpy="0 0 0"/> 
</joint> 


<!-- Robot3 -->
<link name="$(arg tf_prefix)/yball_stem6">
  <gravity>1</gravity>
  <inertial>
    <origin xyz="0 0 0" rpy="0 0 0"/>
    <mass value=".00001"/>
    <inertia ixx="0.0000004" ixy="0.0" ixz="0.0" iyy="0.0000004" iyz="0.0" izz="0.0000004" />
  </inertial>
  <visual><geometry><sphere radius=".00001"/></geometry></visual>
  <collision><geometry><sphere radius=".00001"/></geometry></collision>
</link>
<gazebo reference="$(arg tf_prefix)/yball_stem6">
  <material>Gazebo/Green</material>
</gazebo>



<joint name="$(arg tf_prefix)/stem6y" type="revolute" >
  <parent link="/Plink1M" />
  <child link="$(arg tf_prefix)/yball_stem6" />
  <origin xyz="0.18 0.5 0.44" rpy="0 0 0"/> <!-- <origin xyz="0.18 0.06 1.19" rpy="0 0 0"/> in case of reference /base_link -->
  <axis xyz="0 1 0" />
  <dynamics damping="0.0001" friction="0.0002"/>
  <limit 
      lower="-${pi}" upper="${pi}"
      effort="1" velocity="0.1" />
</joint>
<!--<transmission name="tran_stem6y">
  <type>transmission_interface/SimpleTransmission</type>
  <joint name="$(arg tf_prefix)/stem6y">
    <hardwareInterface>hardware_interface/EffortJointInterface</hardwareInterface>
  </joint>
  <actuator name="$(arg tf_prefix)/act_stem6y">
    <hardwareInterface>hardware_interface/EffortJointInterface</hardwareInterface>
    <mechanicalReduction>1</mechanicalReduction>
  </actuator>
</transmission> -->


<link name="$(arg tf_prefix)/xball_stem6">
  <gravity>1</gravity>
  <inertial>
    <origin xyz="0 0 0" rpy="0 0 0"/>
    <mass value=".00001"/>
    <inertia ixx="0.0000004" ixy="0.0" ixz="0.0" iyy="0.0000004" iyz="0.0" izz="0.0000004" />
  </inertial>
  <visual><geometry><sphere radius=".00001"/></geometry></visual>
  <collision><geometry><sphere radius=".00001"/></geometry></collision>
</link>
<gazebo reference="$(arg tf_prefix)/xball_stem6">
  <material>Gazebo/Green</material>
</gazebo>


<joint name="$(arg tf_prefix)/stem6x" type="revolute" >
  <parent link="$(arg tf_prefix)/yball_stem6"/>
  <child link="$(arg tf_prefix)/xball_stem6"/>
  <origin xyz="0 0 0" rpy="0 0 0"/> 
  <axis xyz="1 0 0" />
  <dynamics damping="0.0001" friction="0.0002" />
  <limit 
      lower="-${pi}" upper="${pi}"
      effort="1" velocity="0.1" />
</joint>
<!--<transmission name="tran_stem6x">
  <type>transmission_interface/SimpleTransmission</type>
  <joint name="$(arg tf_prefix)/stem6x">
    <hardwareInterface>hardware_interface/EffortJointInterface</hardwareInterface>
  </joint>
  <actuator name="$(arg tf_prefix)/act_stem6x">
    <hardwareInterface>hardware_interface/EffortJointInterface</hardwareInterface>
    <mechanicalReduction>1</mechanicalReduction>
  </actuator>
</transmission> -->

<!-- Define stem of straw3 -->
<link name="$(arg tf_prefix)/stem6">
  <gravity>1</gravity>
  <inertial>
    <origin xyz="0 0 0" rpy="0 0 0"/>
    <mass value="0.0001"/>
    <inertia
      ixx="0.0000000005" ixy="0.0" ixz="0.0"
      iyy="0.0000000005" iyz="0.0" 
      izz="0.0000000005"/>
  </inertial>
  <collision>
    <geometry>
		<cylinder length="0.15" radius="0.003"/>
    </geometry>
    <material name="green">
      <color rgba="0 ${128/255} 0 1"/>
    </material>
    <origin xyz="0 0 -0.075" rpy="0 0 0"/>
  </collision>
  <visual>
    <geometry>
		<cylinder length="0.15" radius="0.003"/>
    </geometry>
    <material name="green">
      <color rgba="0 ${128/255} 0 1"/>
    </material>
    <origin xyz="0 0 -0.075" rpy="0 0 0"/>
  </visual>
</link>
<gazebo reference="$(arg tf_prefix)/stem6">
  <mu1>0.01</mu1>
  <mu2>0.01</mu2>
  <selfCollide>true</selfCollide>
  <maxContacts>2</maxContacts>
  <minDepth>0</minDepth>
  <maxVel>0.01</maxVel>
  <kp  value="1" />
  <kd  value="0.1" /> 
  <material>Gazebo/Green</material>
</gazebo>


<joint name="$(arg tf_prefix)/xball_stem6" type="fixed">
  <parent link="$(arg tf_prefix)/xball_stem6"/>
  <child link="$(arg tf_prefix)/stem6"/>
  <origin xyz="0 0 0" rpy="0 0 0"/>  
</joint>

<!-- <joint name="$(arg tf_prefix)/tabletop28_stem6" type="revolute">
  <parent link="/base_link"/>
  <child link="$(arg tf_prefix)/stem6"/>
  <origin xyz="0.18 0.06 1.19" rpy="0 0 0"/>  
  <axis xyz="0 1 0" />
  <dynamics damping="10" friction="200" />
  <limit 
      lower="-${pi/2}" upper="${pi/2}"
      effort="10" velocity="0.1" />
</joint> 
<transmission name="tran_stem6">
  <type>transmission_interface/SimpleTransmission</type>
  <joint name="$(arg tf_prefix)/tabletop28_stem6">
    <hardwareInterface>hardware_interface/EffortJointInterface</hardwareInterface>
  </joint>
  <actuator name="$(arg tf_prefix)/act_stem6y">
    <hardwareInterface>hardware_interface/EffortJointInterface</hardwareInterface>
    <mechanicalReduction>1</mechanicalReduction>
  </actuator>
</transmission> --> 


<!-- Define straw2 -->
<link name="$(arg tf_prefix)/straw6">
  <gravity>1</gravity>
  <inertial>
    <origin xyz="0 0 0" rpy="0 0 0"/>
    <mass value="0.002"/>
    <inertia
      ixx="0.00000018" ixy="0.0" ixz="0.0"
      iyy="0.00000018" iyz="0.0" 
      izz="0.00000018"/>
  </inertial>
  <collision>
    <geometry>
    <sphere radius="0.015"/>
    </geometry>
  </collision>
  <visual>
    <geometry>
		<sphere radius="0.015"/>
    </geometry>
    <material name="Red">
      <color rgba="1 0 0 1"/>
    </material>
  </visual>
</link>
<gazebo reference="$(arg tf_prefix)/straw6">
  <mu1>0.01</mu1>
  <mu2>0.01</mu2>
  <selfCollide>true</selfCollide>
  <maxContacts>2</maxContacts>
  <minDepth>0</minDepth>
  <maxVel>0.01</maxVel>
  <kp  value="1" />
  <kd  value="0.1" /> 
  <material>Gazebo/Red</material>
</gazebo>


<joint name="$(arg tf_prefix)/straw6_stem6" type="fixed"> 
  <parent link="$(arg tf_prefix)/stem6"/>
  <child link="$(arg tf_prefix)/straw6"/>
  <origin xyz="0 0 -0.15" rpy="0 0 0"/> 
</joint> 

<gazebo>
  <plugin name="gazebo_ros_control" filename="libgazebo_ros_control.so">  
    <robotSimType>gazebo_ros_control/DefaultRobotHWSim</robotSimType>
    <legacyModeNS>true</legacyModeNS>
    <robotNamespace>/straw_cluster2</robotNamespace>
  </plugin>
</gazebo> 


</robot>

