<?xml version="1.0"?>
<robot xmlns:xacro="http://www.ros.org/wiki/xacro" name="straw_cluster3">

<xacro:arg name="tf_prefix" default=""/>

<!-- Robot1 -->

<!-- Define stem of straw7 -->
<link name="$(arg tf_prefix)/stem7">
  <gravity>1</gravity>
  <inertial>
    <origin xyz="0 0 0" rpy="0 0 0"/>
    <mass value="0.001"/>
    <inertia
      ixx="0.0000000005" ixy="0.0" ixz="0.0"
      iyy="0.0000000005" iyz="0.0" 
      izz="0.0000000005"/>
  </inertial>
  <collision>
    <geometry>
		<cylinder length="0.15" radius="0.003"/>
    </geometry>
    <material name="green">
      <color rgba="0 ${128/255} 0 1"/>
    </material>
    <origin xyz="0 0 -0.075" rpy="0 0 0"/>
  </collision>
  <visual>
    <geometry>
		<cylinder length="0.15" radius="0.003"/>
    </geometry>
    <material name="green">
      <color rgba="0 ${128/255} 0 1"/>
    </material>
    <origin xyz="0 0 -0.075" rpy="0 0 0"/>
  </visual>
</link>
<gazebo reference="$(arg tf_prefix)/stem7">
  <mu1>0.01</mu1>
  <mu2>0.01</mu2>
  <maxContacts>2</maxContacts>
  <minDepth>0</minDepth>
  <maxVel>0.01</maxVel>
  <selfCollide>true</selfCollide>
  <!--<kp  value="1000000.0" />
  <kd  value="1.0" /> -->  
  <material>Gazebo/Green</material>
</gazebo>


<joint name="$(arg tf_prefix)/stem7x" type="revolute" >
  <parent link="$(arg tf_prefix)/base_link"/>
  <child link="$(arg tf_prefix)/stem7"/>
  <origin xyz="-0.15 0.06 1.19" rpy="0 0 0"/> 
  <axis xyz="0 1 0" />
  <!--<dynamics damping="0.001" friction="0.002" />-->
  <limit 
      lower="-${pi}" upper="${pi}" 
      effort="1" velocity="1" /> 
</joint> 


<!-- Define straw7 -->
<link name="$(arg tf_prefix)/straw7">
  <gravity>1</gravity>
  <inertial>
    <origin xyz="0 0 0" rpy="0 0 0"/>
    <mass value="0.002"/> <!-- 0.002-->
    <inertia
      ixx="0.00000018" ixy="0.0" ixz="0.0"
      iyy="0.00000018" iyz="0.0" 
      izz="0.00000018"/>
  </inertial>
  <collision>
    <geometry>
      <sphere radius="0.015"/>
    </geometry>
  </collision>
  <visual>
    <geometry>
		<sphere radius="0.015"/>
    </geometry>
    <material name="Red">
      <color rgba="1 0 0 1"/>
    </material>
  </visual>
</link>
<gazebo reference="$(arg tf_prefix)/straw7">
  <mu1>0.01</mu1>
  <mu2>0.01</mu2>
  <maxContacts>2</maxContacts>
  <minDepth>0</minDepth>
  <maxVel>0.01</maxVel>
  <selfCollide>true</selfCollide>
  <kp  value="1000000.0" />
  <kd  value="1.0" /> 
  <material>Gazebo/Red</material>
</gazebo>


<joint name="$(arg tf_prefix)/straw7_stem7" type="fixed"> 
  <parent link="$(arg tf_prefix)/stem7"/>
  <child link="$(arg tf_prefix)/straw7"/>
  <origin xyz="0 0 -0.15" rpy="0 0 0"/> 
</joint> 


</robot>

