<?xml version="1.0" ?>
<!-- =================================================================================== -->
<!-- |    This document was autogenerated by xacro from Harvesting_extras.xacro        | -->
<!-- |    EDITING THIS FILE BY HAND IS NOT RECOMMENDED                                 | -->
<!-- =================================================================================== -->
<robot name="Harvesting_extras" xmlns:xacro="http://www.ros.org/wiki/xacro">
  <link name="/uvtun_frame">
    <inertial>
      <origin rpy="0 0 0" xyz="0 0 0"/>
      <mass value="1"/>
      <inertia ixx="1.0" ixy="0.0" ixz="0.0" iyy="1.0" iyz="0.0" izz="1.0"/>
    </inertial>
    <visual>
      <geometry>
        <mesh filename="package://thorvald_description/meshes/uv_frame/uv_arc.STL"/>
      </geometry>
      <material name="whiter">
        <color rgba="1 1 1 1"/>
      </material>
    </visual>
  </link>
  <joint name="/base_uvtun_frame" type="fixed">
    <parent link="/base_link"/>
    <child link="/uvtun_frame"/>
    <origin rpy="1.57079632679 0 1.57079632679" xyz="-0.525 -0.66 0.5"/>
  </joint>
  <!-- GPS Sensors-->
  <link name="gps_front">
    <visual>
      <material name="sept_color">
        <color rgba="1 0.8 0 1"/>
      </material>
      <geometry>
        <cylinder length="0.05" radius="0.10"/>
      </geometry>
    </visual>
  </link>
  <link name="gps_back">
    <visual>
      <material name="sept_color">
        <color rgba="1 0.8 0 1"/>
      </material>
      <geometry>
        <cylinder length="0.05" radius="0.10"/>
      </geometry>
    </visual>
  </link>
  <joint name="/gps_back" type="fixed">
    <parent link="/base_link"/>
    <child link="gps_back"/>
    <origin rpy="0 0 0" xyz="-0.51 0 2.1"/>
  </joint>
  <joint name="/gps_front" type="fixed">
    <parent link="/base_link"/>
    <child link="gps_front"/>
    <origin rpy="0 0 0" xyz="0.51 0 2.1"/>
  </joint>
  <gazebo>
    <plugin filename="libhector_gazebo_ros_gps.so" name="gazebo_ros_gps">
      <alwaysOn>1</alwaysOn>
      <updateRate>4.0</updateRate>
      <bodyName>gps_front</bodyName>
      <frameId>front_gps</frameId>
      <topicName>gps_front/fix</topicName>
      <velocityTopicName>gps_front/fix_velocity</velocityTopicName>
      <drift>5.0 5.0 5.0</drift>
      <gaussianNoise>0.1 0.1 0.1</gaussianNoise>
      <velocityDrift>0 0 0</velocityDrift>
      <velocityGaussianNoise>0.1 0.1 0.1</velocityGaussianNoise>
    </plugin>
  </gazebo>
  <gazebo>
    <plugin filename="libhector_gazebo_ros_gps.so" name="gazebo_ros_gps">
      <alwaysOn>1</alwaysOn>
      <updateRate>4.0</updateRate>
      <bodyName>gps_back</bodyName>
      <frameId>back_gps</frameId>
      <topicName>gps_back/fix</topicName>
      <velocityTopicName>gps_back/fix_velocity</velocityTopicName>
      <drift>5.0 5.0 5.0</drift>
      <gaussianNoise>0.1 0.1 0.1</gaussianNoise>
      <velocityDrift>0 0 0</velocityDrift>
      <velocityGaussianNoise>0.1 0.1 0.1</velocityGaussianNoise>
    </plugin>
  </gazebo>
  <!--Laser Sensors-->
  <link name="/hokuyo_front">
    <collision>
      <origin rpy="0 0 0" xyz="0 0 0"/>
      <geometry>
        <box size="0.1 0.1 0.1"/>
      </geometry>
    </collision>
    <visual>
      <origin rpy="0 0 0" xyz="0 0 0"/>
      <geometry>
        <mesh filename="package://thorvald_description/meshes/hokuyo/hokuyo.dae"/>
      </geometry>
    </visual>
    <inertial>
      <mass value="1e-5"/>
      <origin rpy="0 0 0" xyz="0 0 0"/>
      <inertia ixx="1e-6" ixy="0" ixz="0" iyy="1e-6" iyz="0" izz="1e-6"/>
    </inertial>
  </link>
  <link name="/hokuyo_back">
    <collision>
      <origin rpy="0 0 0" xyz="0 0 0"/>
      <geometry>
        <box size="0.1 0.1 0.1"/>
      </geometry>
    </collision>
    <visual>
      <origin rpy="0 0 0" xyz="0 0 0"/>
      <geometry>
        <mesh filename="package://thorvald_description/meshes/hokuyo/hokuyo.dae"/>
      </geometry>
    </visual>
    <inertial>
      <mass value="1e-5"/>
      <origin rpy="0 0 0" xyz="0 0 0"/>
      <inertia ixx="1e-6" ixy="0" ixz="0" iyy="1e-6" iyz="0" izz="1e-6"/>
    </inertial>
  </link>
  <joint name="base_sens_hokuyo_front" type="fixed">
    <parent link="/top1"/>
    <child link="/hokuyo_front"/>
    <axis xyz="0 1 0"/>
    <origin rpy="0.0 0.0 -0.79" xyz="0.172 -0.152 -0.034"/>
  </joint>
  <joint name="base_sens_hokuyo_back" type="fixed">
    <parent link="/top3"/>
    <child link="/hokuyo_back"/>
    <axis xyz="0 1 0"/>
    <origin rpy="0.0 0.0 -0.79" xyz="0.172 -0.152 -0.034"/>
  </joint>
  <gazebo reference="/hokuyo_front">
    <sensor name="_head_hokuyo_front_sensor" type="ray">
      <pose>0 0 0 0 0 0</pose>
      <visualize>true</visualize>
      <update_rate>40</update_rate>
      <always_on>1</always_on>
      <ray>
        <scan>
          <horizontal>
            <samples>720</samples>
            <resolution>1</resolution>
            <min_angle>-2.18</min_angle>
            <max_angle>2.36</max_angle>
          </horizontal>
        </scan>
        <range>
          <min>0.10</min>
          <max>30.0</max>
          <resolution>0.01</resolution>
        </range>
        <noise>
          <type>gaussian</type>
          <!-- Noise parameters based on published spec for Hokuyo laser
               achieving "+-30mm" accuracy at range < 10m.  A mean of 0.0m and
               stddev of 0.01m will put 99.7% of samples within 0.03m of the true
               reading. -->
          <mean>0.0</mean>
          <stddev>0.01</stddev>
        </noise>
      </ray>
      <plugin filename="libgazebo_ros_laser.so" name="_hokuyo_front_node">
        <topicName>scan_front</topicName>
        <frameName>hokuyo_front</frameName>
      </plugin>
    </sensor>
  </gazebo>
  <gazebo reference="/hokuyo_back">
    <sensor name="_head_hokuyo_back_sensor" type="ray">
      <pose>0 0 0 0 0 0</pose>
      <visualize>true</visualize>
      <update_rate>40</update_rate>
      <always_on>1</always_on>
      <ray>
        <scan>
          <horizontal>
            <samples>720</samples>
            <resolution>1</resolution>
            <min_angle>-2.18</min_angle>
            <max_angle>2.36</max_angle>
          </horizontal>
        </scan>
        <range>
          <min>0.10</min>
          <max>30.0</max>
          <resolution>0.01</resolution>
        </range>
        <noise>
          <type>gaussian</type>
          <!-- Noise parameters based on published spec for Hokuyo laser
               achieving "+-30mm" accuracy at range < 10m.  A mean of 0.0m and
               stddev of 0.01m will put 99.7% of samples within 0.03m of the true
               reading. -->
          <mean>0.0</mean>
          <stddev>0.01</stddev>
        </noise>
      </ray>
      <plugin filename="libgazebo_ros_laser.so" name="_hokuyo_back_node">
        <topicName>scan_back</topicName>
        <frameName>hokuyo_back</frameName>
      </plugin>
    </sensor>
  </gazebo>
  <!-- Define link1 of 3dof Manip -->
  <link name="/Plink1">
    <inertial>
      <origin rpy="0 0 0" xyz="0 0 0"/>
      <mass value="1"/>
      <inertia ixx="1.0" ixy="0.0" ixz="0.0" iyy="1.0" iyz="0.0" izz="1.0"/>
    </inertial>
    <visual>
      <geometry>
        <mesh filename="package://graspberry_description/scara_arm/meshes/Plink1.stl"/>
      </geometry>
      <material name="whiter">
        <color rgba="1 1 1 1"/>
      </material>
    </visual>
  </link>
  <gazebo reference="/Plink1">
    <material>Gazebo/White</material>
  </gazebo>
  <joint name="/uvtun_frame_Plink1" type="fixed">
    <parent link="/uvtun_frame"/>
    <child link="/Plink1"/>
    <origin rpy="1.57079632679 0 0" xyz="0.09 0.6 0.53"/>
    <!-- xyz="0.03325 0.6 0.669" -->
  </joint>
  <!-- Define Transformation from parent uv_tun to child Plink1 frame -->
  <!-- Define plate of 3dof Manip -->
  <link name="/arm_plate">
    <inertial>
      <origin rpy="0 0 0" xyz="0 0 0"/>
      <mass value="1"/>
      <inertia ixx="1.0" ixy="0.0" ixz="0.0" iyy="1.0" iyz="0.0" izz="1.0"/>
    </inertial>
    <visual>
      <geometry>
        <mesh filename="package://graspberry_description/scara_arm/meshes/plate.stl"/>
      </geometry>
      <material name="whiter">
        <color rgba="1 1 1 1"/>
      </material>
    </visual>
  </link>
  <gazebo reference="/arm_plate">
    <material>Gazebo/White</material>
  </gazebo>
  <joint name="/Plink1_plate" type="prismatic">
    <parent link="/Plink1"/>
    <child link="/arm_plate"/>
    <origin rpy="3.14159265359 0 0" xyz="0.04375 0 0"/>
    <!-- 0.04375 0 -0.1735 -->
    <axis xyz="0 0 1"/>
    <limit effort="100" lower="0" upper="0.51" velocity="1"/>
  </joint>
  <transmission name="tran10">
    <type>transmission_interface/SimpleTransmission</type>
    <joint name="/Plink1_plate">
      <hardwareInterface>hardware_interface/EffortJointInterface</hardwareInterface>
    </joint>
    <actuator name="/prismatic_arm_act">
      <hardwareInterface>hardware_interface/EffortJointInterface</hardwareInterface>
      <mechanicalReduction>1</mechanicalReduction>
    </actuator>
  </transmission>
  <!-- Define link2 of 3dof Manip -->
  <link name="/R1link2">
    <inertial>
      <origin rpy="0 0 0" xyz="0 0 0"/>
      <mass value="1"/>
      <inertia ixx="1.0" ixy="0.0" ixz="0.0" iyy="1.0" iyz="0.0" izz="1.0"/>
    </inertial>
    <visual>
      <geometry>
        <mesh filename="package://graspberry_description/scara_arm/meshes/R1link2.stl"/>
      </geometry>
      <material name="whiter">
        <color rgba="1 1 1 1"/>
      </material>
    </visual>
  </link>
  <gazebo reference="/R1link2">
    <material>Gazebo/White</material>
  </gazebo>
  <joint name="/plate_R1link2" type="revolute">
    <parent link="/arm_plate"/>
    <child link="/R1link2"/>
    <origin rpy="0 0 0" xyz="0.06075 -0.13025 0"/>
    <!-- 0 0 -${pi/6} -->
    <axis xyz="0 0 1"/>
    <limit effort="100" lower="0" upper="-3.14" velocity="1"/>
  </joint>
  <transmission name="tran02">
    <type>transmission_interface/SimpleTransmission</type>
    <joint name="/plate_R1link2">
      <hardwareInterface>hardware_interface/EffortJointInterface</hardwareInterface>
    </joint>
    <actuator name="/plate_R1link2_act">
      <hardwareInterface>hardware_interface/EffortJointInterface</hardwareInterface>
      <mechanicalReduction>1</mechanicalReduction>
    </actuator>
  </transmission>
  <!-- Define Transformation from parent Plink1 to child R1link2 frame -->
  <!-- Define link3 of 3dof Manip -->
  <link name="/R2link3">
    <inertial>
      <origin rpy="0 0 0" xyz="0 0 0"/>
      <mass value="1"/>
      <inertia ixx="1.0" ixy="0.0" ixz="0.0" iyy="1.0" iyz="0.0" izz="1.0"/>
    </inertial>
    <visual>
      <geometry>
        <mesh filename="package://graspberry_description/scara_arm/meshes/R2link3.STL"/>
      </geometry>
      <material name="whiter">
        <color rgba="1 1 1 1"/>
      </material>
    </visual>
  </link>
  <gazebo reference="/R2link3">
    <material>Gazebo/White</material>
  </gazebo>
  <joint name="/R1link2_R2link3" type="revolute">
    <parent link="/R1link2"/>
    <child link="/R2link3"/>
    <origin rpy="0 0 0.523598775598" xyz="0.014 0.265 0"/>
    <!-- 0 0 -${pi/2} -->
    <axis xyz="0 0 1"/>
    <limit effort="100" lower="0" upper="3.14" velocity="1"/>
  </joint>
  <transmission name="tran23">
    <type>transmission_interface/SimpleTransmission</type>
    <joint name="/R1link2_R2link3">
      <hardwareInterface>hardware_interface/EffortJointInterface</hardwareInterface>
    </joint>
    <actuator name="/R1link2_R2link3_act">
      <hardwareInterface>hardware_interface/EffortJointInterface</hardwareInterface>
      <mechanicalReduction>1</mechanicalReduction>
    </actuator>
  </transmission>
  <!-- Define Transformation from parent R1link2 to child R2link3 frame -->
  <!-- Add 2nd arm on opposite side f reference frame of the uvtun -->
  <!-- Define link1 of 3dof Manip -->
  <link name="/Plink1M">
    <inertial>
      <origin rpy="0 0 0" xyz="0 0 0"/>
      <mass value="1"/>
      <inertia ixx="1.0" ixy="0.0" ixz="0.0" iyy="1.0" iyz="0.0" izz="1.0"/>
    </inertial>
    <visual>
      <geometry>
        <mesh filename="package://graspberry_description/scara_arm/meshes/Plink1-Mirror.stl"/>
      </geometry>
      <material name="whiter">
        <color rgba="1 1 1 1"/>
      </material>
    </visual>
  </link>
  <gazebo reference="/Plink1M">
    <material>Gazebo/White</material>
  </gazebo>
  <joint name="/uvtun_frame_Plink1M" type="fixed">
    <parent link="/uvtun_frame"/>
    <child link="/Plink1M"/>
    <origin rpy="1.5707 3.14159265359 0" xyz="1.2305 0.6 0.53"/>
    <!-- 1.23375 0.6 0.669 -->
  </joint>
  <!-- Define Transformation from parent uv_tun to child Plink1 frame -->
  <!-- Define plate of 3dof Manip -->
  <link name="/arm_plateM">
    <inertial>
      <origin rpy="0 0 0" xyz="0 0 0"/>
      <mass value="1"/>
      <inertia ixx="1.0" ixy="0.0" ixz="0.0" iyy="1.0" iyz="0.0" izz="1.0"/>
    </inertial>
    <visual>
      <geometry>
        <mesh filename="package://graspberry_description/scara_arm/meshes/plate-Mirror.stl"/>
      </geometry>
      <material name="whiter">
        <color rgba="1 1 1 1"/>
      </material>
    </visual>
  </link>
  <gazebo reference="/arm_plate">
    <material>Gazebo/White</material>
  </gazebo>
  <joint name="/Plink1_plateM" type="prismatic">
    <parent link="/Plink1M"/>
    <child link="/arm_plateM"/>
    <origin rpy="3.14159265359 0 0" xyz="0.04375 0 0"/>
    <axis xyz="0 0 1"/>
    <limit effort="100" lower="0" upper="0.51" velocity="1"/>
  </joint>
  <transmission name="tran10M">
    <type>transmission_interface/SimpleTransmission</type>
    <joint name="/Plink1_plateM">
      <hardwareInterface>hardware_interface/EffortJointInterface</hardwareInterface>
    </joint>
    <actuator name="/prismatic_arm_actM">
      <hardwareInterface>hardware_interface/EffortJointInterface</hardwareInterface>
      <mechanicalReduction>1</mechanicalReduction>
    </actuator>
  </transmission>
  <!-- Define link2 of 3dof Manip -->
  <link name="/R1link2M">
    <inertial>
      <origin rpy="0 0 0" xyz="0 0 0"/>
      <mass value="1"/>
      <inertia ixx="1.0" ixy="0.0" ixz="0.0" iyy="1.0" iyz="0.0" izz="1.0"/>
    </inertial>
    <visual>
      <geometry>
        <mesh filename="package://graspberry_description/scara_arm/meshes/R1link2-Mirror.stl"/>
      </geometry>
      <material name="whiter">
        <color rgba="1 1 1 1"/>
      </material>
    </visual>
  </link>
  <gazebo reference="/R1link2M">
    <material>Gazebo/White</material>
  </gazebo>
  <joint name="/plate_R1link2M" type="revolute">
    <parent link="/arm_plateM"/>
    <child link="/R1link2M"/>
    <origin rpy="0 0 0" xyz="0.06075 -0.13025 0"/>
    <axis xyz="0 0 1"/>
    <limit effort="100" lower="-1.5707" upper="1.5707" velocity="1"/>
  </joint>
  <transmission name="tran02M">
    <type>transmission_interface/SimpleTransmission</type>
    <joint name="/plate_R1link2M">
      <hardwareInterface>hardware_interface/EffortJointInterface</hardwareInterface>
    </joint>
    <actuator name="/plate_R1link2M_act">
      <hardwareInterface>hardware_interface/EffortJointInterface</hardwareInterface>
      <mechanicalReduction>1</mechanicalReduction>
    </actuator>
  </transmission>
  <!-- Define Transformation from parent Plink1 to child R1link2 frame -->
  <!-- Define link3 of 3dof Manip -->
  <link name="/R2link3M">
    <inertial>
      <origin rpy="0 0 0" xyz="0 0 0"/>
      <mass value="1"/>
      <inertia ixx="1.0" ixy="0.0" ixz="0.0" iyy="1.0" iyz="0.0" izz="1.0"/>
    </inertial>
    <visual>
      <geometry>
        <mesh filename="package://graspberry_description/scara_arm/meshes/R2link3-Mirror.STL"/>
      </geometry>
      <material name="whiter">
        <color rgba="1 1 1 1"/>
      </material>
    </visual>
  </link>
  <gazebo reference="/R2link3M">
    <material>Gazebo/White</material>
  </gazebo>
  <joint name="/R1link2_R2link3M" type="revolute">
    <parent link="/R1link2M"/>
    <child link="/R2link3M"/>
    <origin rpy="0 0 0.523598775598" xyz="0.014 0.265 0"/>
    <axis xyz="0 0 1"/>
    <limit effort="100" lower="0" upper="-3.14" velocity="1"/>
  </joint>
  <transmission name="tran23M">
    <type>transmission_interface/SimpleTransmission</type>
    <joint name="/R1link2_R2link3M">
      <hardwareInterface>hardware_interface/EffortJointInterface</hardwareInterface>
    </joint>
    <actuator name="/R1link2_R2link3M_act">
      <hardwareInterface>hardware_interface/EffortJointInterface</hardwareInterface>
      <mechanicalReduction>1</mechanicalReduction>
    </actuator>
  </transmission>
  <!-- Define Transformation from parent R1link2 to child R2link3 frame -->
  <gazebo>
    <plugin filename="libgazebo_ros_control.so" name="gazebo_ros_control">
      <!-- libgazebo_ros_control.so is generated in devel/lib after compilation -->
      <robotSimType>gazebo_ros_control/DefaultRobotHWSim</robotSimType>
      <legacyModeNS>true</legacyModeNS>
      <robotNamespace>/scara_arm</robotNamespace>
    </plugin>
  </gazebo>
</robot>

