<?xml version="1.0" ?>
<!-- =================================================================================== -->
<!-- |    This document was autogenerated by xacro from PRRarm_extras.xacro            | -->
<!-- |    EDITING THIS FILE BY HAND IS NOT RECOMMENDED                                 | -->
<!-- =================================================================================== -->
<robot name="PRRarm" xmlns:xacro="http://www.ros.org/wiki/xacro">
  <!-- Define link1 of 3dof Manip -->
  <link name="/Plink1">
    <inertial>
      <origin rpy="0 0 0" xyz="0 0 0"/>
      <mass value="1"/>
      <inertia ixx="1.0" ixy="0.0" ixz="0.0" iyy="1.0" iyz="0.0" izz="1.0"/>
    </inertial>
    <visual>
      <geometry>
        <mesh filename="package://graspberry_description/scara_arm/meshes/Plink1.stl"/>
      </geometry>
      <material name="whiter">
        <color rgba="1 1 1 1"/>
      </material>
    </visual>
  </link>
  <gazebo reference="/Plink1">
    <material>Gazebo/White</material>
  </gazebo>
  <joint name="/uvtun_frame_Plink1" type="fixed">
    <parent link="/uvtun_frame"/>
    <child link="/Plink1"/>
    <origin rpy="1.57079632679 0 0" xyz="0.09 0.6 0.53"/>
    <!-- xyz="0.03325 0.6 0.669" -->
  </joint>
  <!-- Define Transformation from parent uv_tun to child Plink1 frame -->
  <!-- Define plate of 3dof Manip -->
  <link name="/arm_plate">
    <inertial>
      <origin rpy="0 0 0" xyz="0 0 0"/>
      <mass value="1"/>
      <inertia ixx="1.0" ixy="0.0" ixz="0.0" iyy="1.0" iyz="0.0" izz="1.0"/>
    </inertial>
    <visual>
      <geometry>
        <mesh filename="package://graspberry_description/scara_arm/meshes/plate.stl"/>
      </geometry>
      <material name="whiter">
        <color rgba="1 1 1 1"/>
      </material>
    </visual>
  </link>
  <gazebo reference="/arm_plate">
    <material>Gazebo/White</material>
  </gazebo>
  <joint name="/Plink1_plate" type="prismatic">
    <parent link="/Plink1"/>
    <child link="/arm_plate"/>
    <origin rpy="3.14159265359 0 0" xyz="0.04375 0 0"/>
    <!-- 0.04375 0 -0.1735 -->
    <axis xyz="0 0 1"/>
    <limit effort="100" lower="0" upper="0.51" velocity="1"/>
  </joint>
  <transmission name="tran10">
    <type>transmission_interface/SimpleTransmission</type>
    <joint name="/Plink1_plate">
      <hardwareInterface>hardware_interface/EffortJointInterface</hardwareInterface>
    </joint>
    <actuator name="/prismatic_arm_act">
      <hardwareInterface>hardware_interface/EffortJointInterface</hardwareInterface>
      <mechanicalReduction>1</mechanicalReduction>
    </actuator>
  </transmission>
  <!-- Define link2 of 3dof Manip -->
  <link name="/R1link2">
    <inertial>
      <origin rpy="0 0 0" xyz="0 0 0"/>
      <mass value="1"/>
      <inertia ixx="1.0" ixy="0.0" ixz="0.0" iyy="1.0" iyz="0.0" izz="1.0"/>
    </inertial>
    <visual>
      <geometry>
        <mesh filename="package://graspberry_description/scara_arm/meshes/R1link2.stl"/>
      </geometry>
      <material name="whiter">
        <color rgba="1 1 1 1"/>
      </material>
    </visual>
  </link>
  <gazebo reference="/R1link2">
    <material>Gazebo/White</material>
  </gazebo>
  <joint name="/plate_R1link2" type="revolute">
    <parent link="/arm_plate"/>
    <child link="/R1link2"/>
    <origin rpy="0 0 0" xyz="0.06075 -0.13025 0"/>
    <!-- 0 0 -${pi/6} -->
    <axis xyz="0 0 1"/>
    <limit effort="100" lower="0" upper="-3.14" velocity="1"/>
  </joint>
  <transmission name="tran02">
    <type>transmission_interface/SimpleTransmission</type>
    <joint name="/plate_R1link2">
      <hardwareInterface>hardware_interface/EffortJointInterface</hardwareInterface>
    </joint>
    <actuator name="/plate_R1link2_act">
      <hardwareInterface>hardware_interface/EffortJointInterface</hardwareInterface>
      <mechanicalReduction>1</mechanicalReduction>
    </actuator>
  </transmission>
  <!-- Define Transformation from parent Plink1 to child R1link2 frame -->
  <!-- Define link3 of 3dof Manip -->
  <link name="/R2link3">
    <inertial>
      <origin rpy="0 0 0" xyz="0 0 0"/>
      <mass value="1"/>
      <inertia ixx="1.0" ixy="0.0" ixz="0.0" iyy="1.0" iyz="0.0" izz="1.0"/>
    </inertial>
    <visual>
      <geometry>
        <mesh filename="package://graspberry_description/scara_arm/meshes/R2link3.STL"/>
      </geometry>
      <material name="whiter">
        <color rgba="1 1 1 1"/>
      </material>
    </visual>
  </link>
  <gazebo reference="/R2link3">
    <material>Gazebo/White</material>
  </gazebo>
  <joint name="/R1link2_R2link3" type="revolute">
    <parent link="/R1link2"/>
    <child link="/R2link3"/>
    <origin rpy="0 0 0.523598775598" xyz="0.014 0.265 0"/>
    <!-- 0 0 -${pi/2} -->
    <axis xyz="0 0 1"/>
    <limit effort="100" lower="0" upper="3.14" velocity="1"/>
  </joint>
  <transmission name="tran23">
    <type>transmission_interface/SimpleTransmission</type>
    <joint name="/R1link2_R2link3">
      <hardwareInterface>hardware_interface/EffortJointInterface</hardwareInterface>
    </joint>
    <actuator name="/R1link2_R2link3_act">
      <hardwareInterface>hardware_interface/EffortJointInterface</hardwareInterface>
      <mechanicalReduction>1</mechanicalReduction>
    </actuator>
  </transmission>
  <!-- Define Transformation from parent R1link2 to child R2link3 frame -->
  <!-- Add 2nd arm on opposite side f reference frame of the uvtun -->
  <!-- Define link1 of 3dof Manip -->
  <link name="/Plink1M">
    <inertial>
      <origin rpy="0 0 0" xyz="0 0 0"/>
      <mass value="1"/>
      <inertia ixx="1.0" ixy="0.0" ixz="0.0" iyy="1.0" iyz="0.0" izz="1.0"/>
    </inertial>
    <visual>
      <geometry>
        <mesh filename="package://graspberry_description/scara_arm/meshes/Plink1-Mirror.stl"/>
      </geometry>
      <material name="whiter">
        <color rgba="1 1 1 1"/>
      </material>
    </visual>
  </link>
  <gazebo reference="/Plink1M">
    <material>Gazebo/White</material>
  </gazebo>
  <joint name="/uvtun_frame_Plink1M" type="fixed">
    <parent link="/uvtun_frame"/>
    <child link="/Plink1M"/>
    <origin rpy="1.5707 3.14159265359 0" xyz="1.2305 0.6 0.53"/>
    <!-- 1.23375 0.6 0.669 -->
  </joint>
  <!-- Define Transformation from parent uv_tun to child Plink1 frame -->
  <!-- Define plate of 3dof Manip -->
  <link name="/arm_plateM">
    <inertial>
      <origin rpy="0 0 0" xyz="0 0 0"/>
      <mass value="1"/>
      <inertia ixx="1.0" ixy="0.0" ixz="0.0" iyy="1.0" iyz="0.0" izz="1.0"/>
    </inertial>
    <visual>
      <geometry>
        <mesh filename="package://graspberry_description/scara_arm/meshes/plate-Mirror.stl"/>
      </geometry>
      <material name="whiter">
        <color rgba="1 1 1 1"/>
      </material>
    </visual>
  </link>
  <gazebo reference="/arm_plate">
    <material>Gazebo/White</material>
  </gazebo>
  <joint name="/Plink1_plateM" type="prismatic">
    <parent link="/Plink1M"/>
    <child link="/arm_plateM"/>
    <origin rpy="3.14159265359 0 0" xyz="0.04375 0 0"/>
    <axis xyz="0 0 1"/>
    <limit effort="100" lower="0" upper="0.51" velocity="1"/>
  </joint>
  <transmission name="tran10M">
    <type>transmission_interface/SimpleTransmission</type>
    <joint name="/Plink1_plateM">
      <hardwareInterface>hardware_interface/EffortJointInterface</hardwareInterface>
    </joint>
    <actuator name="/prismatic_arm_actM">
      <hardwareInterface>hardware_interface/EffortJointInterface</hardwareInterface>
      <mechanicalReduction>1</mechanicalReduction>
    </actuator>
  </transmission>
  <!-- Define link2 of 3dof Manip -->
  <link name="/R1link2M">
    <inertial>
      <origin rpy="0 0 0" xyz="0 0 0"/>
      <mass value="1"/>
      <inertia ixx="1.0" ixy="0.0" ixz="0.0" iyy="1.0" iyz="0.0" izz="1.0"/>
    </inertial>
    <visual>
      <geometry>
        <mesh filename="package://graspberry_description/scara_arm/meshes/R1link2-Mirror.stl"/>
      </geometry>
      <material name="whiter">
        <color rgba="1 1 1 1"/>
      </material>
    </visual>
  </link>
  <gazebo reference="/R1link2M">
    <material>Gazebo/White</material>
  </gazebo>
  <joint name="/plate_R1link2M" type="revolute">
    <parent link="/arm_plateM"/>
    <child link="/R1link2M"/>
    <origin rpy="0 0 0" xyz="0.06075 -0.13025 0"/>
    <axis xyz="0 0 1"/>
    <limit effort="100" lower="-1.5707" upper="1.5707" velocity="1"/>
  </joint>
  <transmission name="tran02M">
    <type>transmission_interface/SimpleTransmission</type>
    <joint name="/plate_R1link2M">
      <hardwareInterface>hardware_interface/EffortJointInterface</hardwareInterface>
    </joint>
    <actuator name="/plate_R1link2M_act">
      <hardwareInterface>hardware_interface/EffortJointInterface</hardwareInterface>
      <mechanicalReduction>1</mechanicalReduction>
    </actuator>
  </transmission>
  <!-- Define Transformation from parent Plink1 to child R1link2 frame -->
  <!-- Define link3 of 3dof Manip -->
  <link name="/R2link3M">
    <inertial>
      <origin rpy="0 0 0" xyz="0 0 0"/>
      <mass value="1"/>
      <inertia ixx="1.0" ixy="0.0" ixz="0.0" iyy="1.0" iyz="0.0" izz="1.0"/>
    </inertial>
    <visual>
      <geometry>
        <mesh filename="package://graspberry_description/scara_arm/meshes/R2link3-Mirror.STL"/>
      </geometry>
      <material name="whiter">
        <color rgba="1 1 1 1"/>
      </material>
    </visual>
  </link>
  <gazebo reference="/R2link3M">
    <material>Gazebo/White</material>
  </gazebo>
  <joint name="/R1link2_R2link3M" type="revolute">
    <parent link="/R1link2M"/>
    <child link="/R2link3M"/>
    <origin rpy="0 0 0.523598775598" xyz="0.014 0.265 0"/>
    <axis xyz="0 0 1"/>
    <limit effort="100" lower="0" upper="-3.14" velocity="1"/>
  </joint>
  <transmission name="tran23M">
    <type>transmission_interface/SimpleTransmission</type>
    <joint name="/R1link2_R2link3M">
      <hardwareInterface>hardware_interface/EffortJointInterface</hardwareInterface>
    </joint>
    <actuator name="/R1link2_R2link3M_act">
      <hardwareInterface>hardware_interface/EffortJointInterface</hardwareInterface>
      <mechanicalReduction>1</mechanicalReduction>
    </actuator>
  </transmission>
  <!-- Define Transformation from parent R1link2 to child R2link3 frame -->
  <gazebo>
    <plugin filename="libgazebo_ros_control.so" name="gazebo_ros_control">
      <!-- libgazebo_ros_control.so is generated in devel/lib after compilation -->
      <robotSimType>gazebo_ros_control/DefaultRobotHWSim</robotSimType>
      <legacyModeNS>true</legacyModeNS>
      <robotNamespace>/scara_arm</robotNamespace>
    </plugin>
  </gazebo>
</robot>

