<?xml version="1.0"?>
<robot xmlns:xacro="http://www.ros.org/wiki/xacro" name="PRRarm">

<xacro:arg name="tf_prefix" default=""/>


<!-- Define link1 of 3dof Manip -->
<link name="$(arg tf_prefix)/Plink1">
  <inertial>
    <origin xyz="0 0 0" rpy="0 0 0"/>
    <mass value="1"/>
    <inertia
      ixx="1.0" ixy="0.0" ixz="0.0"
      iyy="1.0" iyz="0.0" 
      izz="1.0"/>
  </inertial>
  <visual>
    <geometry>
      <mesh filename="package://graspberry_description/scara_arm/meshes/Plink1.stl"/>
    </geometry>
    <material name="whiter">
      <color rgba="1 1 1 1"/>
    </material>
  </visual>
</link>
<gazebo reference="$(arg tf_prefix)/Plink1">
  <material>Gazebo/White</material>
</gazebo>



<joint name="$(arg tf_prefix)/uvtun_frame_Plink1" type="fixed"> 
  <parent link="$(arg tf_prefix)/uvtun_frame"/>
  <child link="$(arg tf_prefix)/Plink1"/>
  <origin xyz="0.09 0.6 0.53" rpy="${pi/2} 0 0"/>  <!-- xyz="0.03325 0.6 0.669" -->
</joint> 


<!-- Define Transformation from parent uv_tun to child Plink1 frame -->

<!-- Define plate of 3dof Manip -->
<link name="$(arg tf_prefix)/arm_plate">
  <inertial>
    <origin xyz="0 0 0" rpy="0 0 0"/>
    <mass value="1"/>
    <inertia
      ixx="1.0" ixy="0.0" ixz="0.0"
      iyy="1.0" iyz="0.0" 
      izz="1.0"/>
  </inertial>
  <visual>
    <geometry>
      <mesh filename="package://graspberry_description/scara_arm/meshes/plate.stl"/>
    </geometry>
    <material name="whiter">
      <color rgba="1 1 1 1"/>
    </material>
  </visual>
</link>
<gazebo reference="$(arg tf_prefix)/arm_plate">
  <material>Gazebo/White</material>
</gazebo>


<joint name="$(arg tf_prefix)/Plink1_plate" type="prismatic">
  <parent link="$(arg tf_prefix)/Plink1"/>
  <child link="$(arg tf_prefix)/arm_plate"/>
  <origin xyz="0.04375 0 0" rpy="${pi} 0 0"/>  <!-- 0.04375 0 -0.1735 -->
  <axis xyz="0 0 1" />
  <limit 
      lower="0" upper="0.51"
      effort="100" velocity="1" />
</joint> 
<transmission name="tran10">
  <type>transmission_interface/SimpleTransmission</type>
  <joint name="$(arg tf_prefix)/Plink1_plate">
    <hardwareInterface>hardware_interface/EffortJointInterface</hardwareInterface>
  </joint>
  <actuator name="$(arg tf_prefix)/prismatic_arm_act">
    <hardwareInterface>hardware_interface/EffortJointInterface</hardwareInterface>
    <mechanicalReduction>1</mechanicalReduction>
  </actuator>
</transmission> 



<!-- Define link2 of 3dof Manip -->
<link name="$(arg tf_prefix)/R1link2">
  <inertial>
    <origin xyz="0 0 0" rpy="0 0 0"/>
    <mass value="1"/>
    <inertia
      ixx="1.0" ixy="0.0" ixz="0.0"
      iyy="1.0" iyz="0.0" 
      izz="1.0"/>
  </inertial>
  <visual>
    <geometry>
      <mesh filename="package://graspberry_description/scara_arm/meshes/R1link2.stl"/>
    </geometry>
    <material name="whiter">
      <color rgba="1 1 1 1"/>
    </material>
  </visual>
</link>
<gazebo reference="$(arg tf_prefix)/R1link2">
  <material>Gazebo/White</material>
</gazebo>



<joint name="$(arg tf_prefix)/plate_R1link2" type="revolute">
  <parent link="$(arg tf_prefix)/arm_plate"/>
  <child link="$(arg tf_prefix)/R1link2"/>
  <origin xyz="0.06075 -0.13025 0" rpy="0 0 0"/>  <!-- 0 0 -${pi/6} -->
  <axis xyz="0 0 1" />
  <limit 
      lower="0" upper="-3.14"
      effort="100" velocity="1" />
</joint> 
<transmission name="tran02">
  <type>transmission_interface/SimpleTransmission</type>
  <joint name="$(arg tf_prefix)/plate_R1link2">
    <hardwareInterface>hardware_interface/EffortJointInterface</hardwareInterface>
  </joint>
  <actuator name="$(arg tf_prefix)/plate_R1link2_act">
    <hardwareInterface>hardware_interface/EffortJointInterface</hardwareInterface>
    <mechanicalReduction>1</mechanicalReduction>
  </actuator>
</transmission>



<!-- Define Transformation from parent Plink1 to child R1link2 frame -->

<!-- Define link3 of 3dof Manip -->
<link name="$(arg tf_prefix)/R2link3">
  <inertial>
    <origin xyz="0 0 0" rpy="0 0 0"/>
    <mass value="1"/>
    <inertia
      ixx="1.0" ixy="0.0" ixz="0.0"
      iyy="1.0" iyz="0.0" 
      izz="1.0"/>
  </inertial>
  <visual>
    <geometry>
      <mesh filename="package://graspberry_description/scara_arm/meshes/R2link3.STL"/>
    </geometry>
    <material name="whiter">
      <color rgba="1 1 1 1"/>
    </material>
  </visual>
</link>
<gazebo reference="$(arg tf_prefix)/R2link3">
  <material>Gazebo/White</material>
</gazebo>


<joint name="$(arg tf_prefix)/R1link2_R2link3" type="revolute">
  <parent link="$(arg tf_prefix)/R1link2"/>
  <child link="$(arg tf_prefix)/R2link3"/>
  <origin xyz="0.014 0.265 0" rpy="0 0 ${pi/6}"/>   <!-- 0 0 -${pi/2} -->
  <axis xyz="0 0 1" />
  <limit 
      lower="0" upper="3.14"
      effort="100" velocity="1" />
</joint> 
<transmission name="tran23">
  <type>transmission_interface/SimpleTransmission</type>
  <joint name="$(arg tf_prefix)/R1link2_R2link3">
    <hardwareInterface>hardware_interface/EffortJointInterface</hardwareInterface>
  </joint>
  <actuator name="$(arg tf_prefix)/R1link2_R2link3_act">
    <hardwareInterface>hardware_interface/EffortJointInterface</hardwareInterface>
    <mechanicalReduction>1</mechanicalReduction>
  </actuator>
</transmission>
<!-- Define Transformation from parent R1link2 to child R2link3 frame -->



<!-- Add 2nd arm on opposite side f reference frame of the uvtun -->
<!-- Define link1 of 3dof Manip -->
<link name="$(arg tf_prefix)/Plink1M">
  <inertial>
    <origin xyz="0 0 0" rpy="0 0 0"/>
    <mass value="1"/>
    <inertia
      ixx="1.0" ixy="0.0" ixz="0.0"
      iyy="1.0" iyz="0.0" 
      izz="1.0"/>
  </inertial>
  <visual>
    <geometry>
      <mesh filename="package://graspberry_description/scara_arm/meshes/Plink1-Mirror.stl"/>
    </geometry>
    <material name="whiter">
      <color rgba="1 1 1 1"/>
    </material>
  </visual>
</link>
<gazebo reference="$(arg tf_prefix)/Plink1M">
  <material>Gazebo/White</material>
</gazebo>


<joint name="$(arg tf_prefix)/uvtun_frame_Plink1M" type="fixed"> 
  <parent link="$(arg tf_prefix)/uvtun_frame"/>
  <child link="$(arg tf_prefix)/Plink1M"/>
  <origin xyz="1.2305 0.6 0.53" rpy="1.5707 ${pi} 0"/> <!-- 1.23375 0.6 0.669 -->
</joint> 
<!-- Define Transformation from parent uv_tun to child Plink1 frame -->


<!-- Define plate of 3dof Manip -->
<link name="$(arg tf_prefix)/arm_plateM">
  <inertial>
    <origin xyz="0 0 0" rpy="0 0 0"/>
    <mass value="1"/>
    <inertia
      ixx="1.0" ixy="0.0" ixz="0.0"
      iyy="1.0" iyz="0.0" 
      izz="1.0"/>
  </inertial>
  <visual>
    <geometry>
      <mesh filename="package://graspberry_description/scara_arm/meshes/plate-Mirror.stl"/>
    </geometry>
    <material name="whiter">
      <color rgba="1 1 1 1"/>
    </material>
  </visual>
</link>
<gazebo reference="$(arg tf_prefix)/arm_plate">
  <material>Gazebo/White</material>
</gazebo>


<joint name="$(arg tf_prefix)/Plink1_plateM" type="prismatic">
  <parent link="$(arg tf_prefix)/Plink1M"/>
  <child link="$(arg tf_prefix)/arm_plateM"/>
  <origin xyz="0.04375 0 0" rpy="${pi} 0 0"/> 
  <axis xyz="0 0 1" />
  <limit 
      lower="0" upper="0.51"
      effort="100" velocity="1" />
</joint> 
<transmission name="tran10M">
  <type>transmission_interface/SimpleTransmission</type>
  <joint name="$(arg tf_prefix)/Plink1_plateM">
    <hardwareInterface>hardware_interface/EffortJointInterface</hardwareInterface>
  </joint>
  <actuator name="$(arg tf_prefix)/prismatic_arm_actM">
    <hardwareInterface>hardware_interface/EffortJointInterface</hardwareInterface>
    <mechanicalReduction>1</mechanicalReduction>
  </actuator>
</transmission> 


<!-- Define link2 of 3dof Manip -->
<link name="$(arg tf_prefix)/R1link2M">
  <inertial>
    <origin xyz="0 0 0" rpy="0 0 0"/>
    <mass value="1"/>
    <inertia
      ixx="1.0" ixy="0.0" ixz="0.0"
      iyy="1.0" iyz="0.0" 
      izz="1.0"/>
  </inertial>
  <visual>
    <geometry>
      <mesh filename="package://graspberry_description/scara_arm/meshes/R1link2-Mirror.stl"/>
    </geometry>
    <material name="whiter">
      <color rgba="1 1 1 1"/>
    </material>
  </visual>
</link>
<gazebo reference="$(arg tf_prefix)/R1link2M">
  <material>Gazebo/White</material>
</gazebo>



<joint name="$(arg tf_prefix)/plate_R1link2M" type="revolute">
  <parent link="$(arg tf_prefix)/arm_plateM"/>
  <child link="$(arg tf_prefix)/R1link2M"/>
  <origin xyz="0.06075 -0.13025 0" rpy="0 0 0"/>  
  <axis xyz="0 0 1" />
  <limit 
      lower="-1.5707" upper="1.5707"
      effort="100" velocity="1" />
</joint> 
<transmission name="tran02M">
  <type>transmission_interface/SimpleTransmission</type>
  <joint name="$(arg tf_prefix)/plate_R1link2M">
    <hardwareInterface>hardware_interface/EffortJointInterface</hardwareInterface>
  </joint>
  <actuator name="$(arg tf_prefix)/plate_R1link2M_act">
    <hardwareInterface>hardware_interface/EffortJointInterface</hardwareInterface>
    <mechanicalReduction>1</mechanicalReduction>
  </actuator>
</transmission> 
<!-- Define Transformation from parent Plink1 to child R1link2 frame -->


<!-- Define link3 of 3dof Manip -->
<link name="$(arg tf_prefix)/R2link3M">
  <inertial>
    <origin xyz="0 0 0" rpy="0 0 0"/>
    <mass value="1"/>
    <inertia
      ixx="1.0" ixy="0.0" ixz="0.0"
      iyy="1.0" iyz="0.0" 
      izz="1.0"/>
  </inertial>
  <visual>
    <geometry>
      <mesh filename="package://graspberry_description/scara_arm/meshes/R2link3-Mirror.STL"/>
    </geometry>
    <material name="whiter">
      <color rgba="1 1 1 1"/>
    </material>
  </visual>
</link>
<gazebo reference="$(arg tf_prefix)/R2link3M">
  <material>Gazebo/White</material>
</gazebo>


<joint name="$(arg tf_prefix)/R1link2_R2link3M" type="revolute">
  <parent link="$(arg tf_prefix)/R1link2M"/>
  <child link="$(arg tf_prefix)/R2link3M"/>
  <origin xyz="0.014 0.265 0" rpy="0 0 ${pi/6}"/> 
  <axis xyz="0 0 1" />
  <limit 
      lower="0" upper="-3.14"
      effort="100" velocity="1" />
</joint> 
<transmission name="tran23M">
  <type>transmission_interface/SimpleTransmission</type>
  <joint name="$(arg tf_prefix)/R1link2_R2link3M">
    <hardwareInterface>hardware_interface/EffortJointInterface</hardwareInterface>
  </joint>
  <actuator name="$(arg tf_prefix)/R1link2_R2link3M_act">
    <hardwareInterface>hardware_interface/EffortJointInterface</hardwareInterface>
    <mechanicalReduction>1</mechanicalReduction>
  </actuator>
</transmission> 
<!-- Define Transformation from parent R1link2 to child R2link3 frame -->


<gazebo>
  <plugin name="gazebo_ros_control" filename="libgazebo_ros_control.so">  <!-- libgazebo_ros_control.so is generated in devel/lib after compilation -->
  	<robotSimType>gazebo_ros_control/DefaultRobotHWSim</robotSimType>
    <legacyModeNS>true</legacyModeNS>
    <robotNamespace>/scara_arm</robotNamespace>
  </plugin>
</gazebo>




</robot>

