<?xml version="1.0" ?>
<!-- =================================================================================== -->
<!-- |    This document was autogenerated by xacro from thorvald_harvester.urdf.xacro  | -->
<!-- |    EDITING THIS FILE BY HAND IS NOT RECOMMENDED                                 | -->
<!-- =================================================================================== -->
<!-- =================================================================================== -->
<!-- |    This document was autogenerated by xacro from thorvald_harvester.xacro       | -->
<!-- |    EDITING THIS FILE BY HAND IS NOT RECOMMENDED                                 | -->
<!-- =================================================================================== -->
<robot name="thorvald_harvester" xmlns:xacro="http://www.ros.org/wiki/xacro">
  <gazebo>
    <plugin filename="libthorvald_gazebo_plugins.so" name="_thorvald_gazebo_plugins">
      <alwaysOn>true</alwaysOn>
      <updateRate>20</updateRate>
      <robotNamespace/>
      <commandTopic>base_state</commandTopic>
      <odometryTopic>odometry/gazebo</odometryTopic>
      <odometryFrame>/odom</odometryFrame>
      <robotBaseFrame>/base_link</robotBaseFrame>
      <steering0>/steering0</steering0>
      <steering1>/steering1</steering1>
      <steering2>/steering2</steering2>
      <steering3>/steering3</steering3>
      <steering4>/steering4</steering4>
      <steering5>/steering5</steering5>
      <steering6>/steering6</steering6>
      <steering7>/steering7</steering7>
      <steering8>/steering8</steering8>
      <steering9>/steering9</steering9>
      <steering10>s/teering10</steering10>
      <wheel0>/wheel0</wheel0>
      <wheel1>/wheel1</wheel1>
      <wheel2>/wheel2</wheel2>
      <wheel3>/wheel3</wheel3>
      <wheel4>/wheel4</wheel4>
      <wheel5>/wheel5</wheel5>
      <wheel6>/wheel6</wheel6>
      <wheel7>/wheel7</wheel7>
      <wheel8>/wheel8</wheel8>
      <wheel9>/wheel9</wheel9>
      <wheel10>/wheel10</wheel10>
    </plugin>
  </gazebo>
  <!--
    <alwaysOn>true</alwaysOn>
    <robotNamespace>thorvald_ii</robotNamespace>
    <steering2>steering2</steering2>
    <steering1>steering1</steering1>
    <steering3>steering3</steering3>
    <steering0>steering0</steering0>
    <publishOdometryMsg>true</publishOdometryMsg>
    <publishOdometryTf>true</publishOdometryTf>
    <robotBaseFrame>base_link</robotBaseFrame>
    <commandTopic>joint_commands</commandTopic>
    <odometryTopic>odom</odometryTopic>
    <odometryFrame>odom</odometryFrame>
    <updateRate>100.0</updateRate>
    <platform_width>0.570</platform_width>
    <wheel_radius>0.400</wheel_radius>
      <torque>5.0</torque>
    </plugin>
  </gazebo> -->
  <!-- MATERIAL DEFINITIONS -->
  <material name="white">
    <color rgba="1 1 1 1"/>
  </material>
  <material name="black">
    <color rgba="0 0 0 1"/>
  </material>
  <material name="red">
    <color rgba="1 0 0 1"/>
  </material>
  <material name="green">
    <color rgba="0 1 0 1"/>
  </material>
  <material name="alu">
    <color rgba="0.75 0.75 0.75 1"/>
  </material>
  <!-- CREATE ROBOT -->
  <!-- Create base link -->
  <link name="/base_link"/>
  <link name="/top0">
    <inertial>
      <origin rpy="0 0 0" xyz="0 0 0"/>
      <mass value="10.21"/>
      <!-- Measured /-->
      <inertia ixx="1.267" ixy="0.086" ixz="0.078" iyy="1.089" iyz="0.150" izz="0.853"/>
      <!-- Measured /-->
    </inertial>
    <visual>
      <geometry>
        <mesh filename="package://thorvald_description/meshes/tower_modules/DUMMY-TOWER-M.stl"/>
      </geometry>
      <material name="white"/>
    </visual>
    <collision>
      <geometry>
        <mesh filename="package://thorvald_description/meshes/tower_modules/DUMMY-TOWER-M.stl"/>
      </geometry>
    </collision>
  </link>
  <joint name="/base_linktop0" type="fixed">
    <parent link="/base_link"/>
    <child link="/top0"/>
    <origin rpy="0 0 3.14159265359" xyz="-0.67792 -0.75 0.65"/>
    <axis xyz="0 0 1"/>
  </joint>
  <link name="/leg0">
    <inertial>
      <origin rpy="0 0 0" xyz="0 0 0"/>
      <mass value="15.64"/>
      <!-- Measured /-->
      <inertia ixx="6.150" ixy="1.310" ixz="0.218" iyy="1.386" iyz="0.873" izz="6.098"/>
      <!-- Measured /-->
    </inertial>
    <visual>
      <origin rpy="0 0 3.14159265359" xyz="0 0 0"/>
      <geometry>
        <mesh filename="package://thorvald_description/meshes/drive_modules/836745-5-DUMMY-RevA.stl"/>
        <!--cylinder length="${leg_length}" radius="${leg_radius}"/-->
        <!--mesh filename="package://thorvald_base/meshes/top_chassis.dae"/-->
      </geometry>
      <material name="white"/>
    </visual>
    <collision>
      <origin rpy="0 0 3.14159265359" xyz="0 0 0"/>
      <geometry>
        <mesh filename="package://thorvald_description/meshes/drive_modules/836745-5-DUMMY-RevA.stl"/>
      </geometry>
    </collision>
  </link>
  <joint name="/steering0" type="continuous">
    <parent link="/base_link"/>
    <child link="/leg0"/>
    <origin rpy="0 0 0" xyz="-0.67792 -0.75 0.2"/>
    <axis xyz="0 0 1"/>
  </joint>
  <transmission name="steering0_tran">
    <type>transmission_interface/SimpleTransmission</type>
    <joint name="/steering0">
      <hardwareInterface>hardware_interface/EffortJointInterface</hardwareInterface>
    </joint>
    <actuator name="steering0_motor">
      <hardwareInterface>hardware_interface/EffortJointInterface</hardwareInterface>
      <mechanicalReduction>1</mechanicalReduction>
    </actuator>
  </transmission>
  <link name="/wheel0_link">
    <inertial>
      <origin rpy="0 0 0" xyz="0 0 0"/>
      <mass value="6.00"/>
      <!-- Measured /-->
      <inertia ixx="0.874" ixy="0.00" ixz="0.00" iyy="1.504" iyz="0.00" izz="0.874"/>
      <!-- Measured /-->
    </inertial>
    <visual>
      <geometry>
        <cylinder length="0.16" radius="0.2"/>
      </geometry>
      <material name="black"/>
    </visual>
    <collision>
      <geometry>
        <cylinder length="0.16" radius="0.2"/>
      </geometry>
    </collision>
  </link>
  <gazebo reference="/wheel0_link">
    <material>Gazebo/Black</material>
    <mu1 value="0.5"/>
    <mu2 value="0.5"/>
    <kp value="1000000.0"/>
    <kd value="1.0"/>
  </gazebo>
  <joint name="/wheel0" type="continuous">
    <parent link="/leg0"/>
    <child link="/wheel0_link"/>
    <origin rpy="-1.57079632679 0 0" xyz="0 0 0"/>
    <axis xyz="0 0 1"/>
    <!--dynamics damping="0" friction="0"/-->
  </joint>
  <transmission name="wheel0_tran">
    <type>transmission_interface/SimpleTransmission</type>
    <joint name="/wheel0">
      <hardwareInterface>hardware_interface/EffortJointInterface</hardwareInterface>
    </joint>
    <actuator name="wheel0_motor">
      <hardwareInterface>hardware_interface/EffortJointInterface</hardwareInterface>
      <mechanicalReduction>1</mechanicalReduction>
    </actuator>
  </transmission>
  <!-- -->
  <!--
    <link name="$(arg tf_prefix)/rod_l_${wheel}">
      <visual>
        <geometry>
          <cylinder length="20" radius="0.01"/>
        </geometry>
	<material name="red" />
      </visual>
    </link>
      
    
    <joint name="$(arg tf_prefix)/rod_l_${wheel}" type="fixed">
      <parent link="$(arg tf_prefix)/${wheel}_link"/>
      <child link="$(arg tf_prefix)/rod_l_${wheel}"/>
      <origin xyz="0 0 10" rpy="0 0 0"/>
      <axis xyz="0 0 1"/>
    </joint>

    <link name="$(arg tf_prefix)/rod_r_${wheel}">
      <visual>
        <geometry>
          <cylinder length="20" radius="0.01"/>
        </geometry>
	<material name="green" />
      </visual>
    </link>
    
    <joint name="$(arg tf_prefix)/rod_r_${wheel}" type="fixed">
      <parent link="$(arg tf_prefix)/${wheel}_link"/>
      <child link="$(arg tf_prefix)/rod_r_${wheel}"/>
      <origin xyz="0 0 -10" rpy="0 0 0"/>
      <axis xyz="0 0 1"/>
    </joint>



    <link name="$(arg tf_prefix)/rod2_l_${wheel}">
      <visual>
        <geometry>
          <cylinder length="80" radius="0.01"/>
        </geometry>
	<material name="red" />
      </visual>
    </link>

    <joint name="$(arg tf_prefix)/rod2_l_${wheel}" type="fixed">
      <parent link="$(arg tf_prefix)/rod_l_${wheel}"/>
      <child link="$(arg tf_prefix)/rod2_l_${wheel}"/>
      <origin xyz="0 0 40" rpy="0 0 0"/>
      <axis xyz="0 0 1"/>
    </joint>

    <link name="$(arg tf_prefix)/rod2_r_${wheel}">
      <visual>
        <geometry>
          <cylinder length="80" radius="0.01"/>
        </geometry>
	<material name="green" />
      </visual>
    </link>
    
    <joint name="$(arg tf_prefix)/rod2_r_${wheel}" type="fixed">
      <parent link="$(arg tf_prefix)/rod_r_${wheel}"/>
      <child link="$(arg tf_prefix)/rod2_r_${wheel}"/>
      <origin xyz="0 0 -40" rpy="0 0 0"/>
      <axis xyz="0 0 1"/>
    </joint>
    -->
  <!-- -->
  <link name="/top1">
    <inertial>
      <origin rpy="0 0 0" xyz="0 0 0"/>
      <mass value="10.21"/>
      <!-- Measured /-->
      <inertia ixx="1.267" ixy="0.086" ixz="0.078" iyy="1.089" iyz="0.150" izz="0.853"/>
      <!-- Measured /-->
    </inertial>
    <visual>
      <geometry>
        <mesh filename="package://thorvald_description/meshes/tower_modules/DUMMY-TOWER-MIRROR-M.stl"/>
      </geometry>
      <material name="white"/>
    </visual>
    <collision>
      <geometry>
        <mesh filename="package://thorvald_description/meshes/tower_modules/DUMMY-TOWER-MIRROR-M.stl"/>
      </geometry>
    </collision>
  </link>
  <joint name="/base_linktop1" type="fixed">
    <parent link="/base_link"/>
    <child link="/top1"/>
    <origin rpy="0 0 0" xyz="0.67792 -0.75 0.65"/>
    <axis xyz="0 0 1"/>
  </joint>
  <link name="/leg1">
    <inertial>
      <origin rpy="0 0 0" xyz="0 0 0"/>
      <mass value="15.64"/>
      <!-- Measured /-->
      <inertia ixx="6.150" ixy="1.310" ixz="0.218" iyy="1.386" iyz="0.873" izz="6.098"/>
      <!-- Measured /-->
    </inertial>
    <visual>
      <origin rpy="0 0 0" xyz="0 0 0"/>
      <geometry>
        <mesh filename="package://thorvald_description/meshes/drive_modules/836745-5-DUMMY-MIRROR-RevA.stl"/>
        <!--cylinder length="${leg_length}" radius="${leg_radius}"/-->
        <!--mesh filename="package://thorvald_base/meshes/top_chassis.dae"/-->
      </geometry>
      <material name="white"/>
    </visual>
    <collision>
      <origin rpy="0 0 0" xyz="0 0 0"/>
      <geometry>
        <mesh filename="package://thorvald_description/meshes/drive_modules/836745-5-DUMMY-MIRROR-RevA.stl"/>
      </geometry>
    </collision>
  </link>
  <joint name="/steering1" type="continuous">
    <parent link="/base_link"/>
    <child link="/leg1"/>
    <origin rpy="0 0 0" xyz="0.67792 -0.75 0.2"/>
    <axis xyz="0 0 1"/>
  </joint>
  <transmission name="steering1_tran">
    <type>transmission_interface/SimpleTransmission</type>
    <joint name="/steering1">
      <hardwareInterface>hardware_interface/EffortJointInterface</hardwareInterface>
    </joint>
    <actuator name="steering1_motor">
      <hardwareInterface>hardware_interface/EffortJointInterface</hardwareInterface>
      <mechanicalReduction>1</mechanicalReduction>
    </actuator>
  </transmission>
  <link name="/wheel1_link">
    <inertial>
      <origin rpy="0 0 0" xyz="0 0 0"/>
      <mass value="6.00"/>
      <!-- Measured /-->
      <inertia ixx="0.874" ixy="0.00" ixz="0.00" iyy="1.504" iyz="0.00" izz="0.874"/>
      <!-- Measured /-->
    </inertial>
    <visual>
      <geometry>
        <cylinder length="0.16" radius="0.2"/>
      </geometry>
      <material name="black"/>
    </visual>
    <collision>
      <geometry>
        <cylinder length="0.16" radius="0.2"/>
      </geometry>
    </collision>
  </link>
  <gazebo reference="/wheel1_link">
    <material>Gazebo/Black</material>
    <mu1 value="0.5"/>
    <mu2 value="0.5"/>
    <kp value="1000000.0"/>
    <kd value="1.0"/>
  </gazebo>
  <joint name="/wheel1" type="continuous">
    <parent link="/leg1"/>
    <child link="/wheel1_link"/>
    <origin rpy="-1.57079632679 0 0" xyz="0 0 0"/>
    <axis xyz="0 0 1"/>
    <!--dynamics damping="0" friction="0"/-->
  </joint>
  <transmission name="wheel1_tran">
    <type>transmission_interface/SimpleTransmission</type>
    <joint name="/wheel1">
      <hardwareInterface>hardware_interface/EffortJointInterface</hardwareInterface>
    </joint>
    <actuator name="wheel1_motor">
      <hardwareInterface>hardware_interface/EffortJointInterface</hardwareInterface>
      <mechanicalReduction>1</mechanicalReduction>
    </actuator>
  </transmission>
  <!-- -->
  <!--
    <link name="$(arg tf_prefix)/rod_l_${wheel}">
      <visual>
        <geometry>
          <cylinder length="20" radius="0.01"/>
        </geometry>
	<material name="red" />
      </visual>
    </link>
      
    
    <joint name="$(arg tf_prefix)/rod_l_${wheel}" type="fixed">
      <parent link="$(arg tf_prefix)/${wheel}_link"/>
      <child link="$(arg tf_prefix)/rod_l_${wheel}"/>
      <origin xyz="0 0 10" rpy="0 0 0"/>
      <axis xyz="0 0 1"/>
    </joint>

    <link name="$(arg tf_prefix)/rod_r_${wheel}">
      <visual>
        <geometry>
          <cylinder length="20" radius="0.01"/>
        </geometry>
	<material name="green" />
      </visual>
    </link>
    
    <joint name="$(arg tf_prefix)/rod_r_${wheel}" type="fixed">
      <parent link="$(arg tf_prefix)/${wheel}_link"/>
      <child link="$(arg tf_prefix)/rod_r_${wheel}"/>
      <origin xyz="0 0 -10" rpy="0 0 0"/>
      <axis xyz="0 0 1"/>
    </joint>



    <link name="$(arg tf_prefix)/rod2_l_${wheel}">
      <visual>
        <geometry>
          <cylinder length="80" radius="0.01"/>
        </geometry>
	<material name="red" />
      </visual>
    </link>

    <joint name="$(arg tf_prefix)/rod2_l_${wheel}" type="fixed">
      <parent link="$(arg tf_prefix)/rod_l_${wheel}"/>
      <child link="$(arg tf_prefix)/rod2_l_${wheel}"/>
      <origin xyz="0 0 40" rpy="0 0 0"/>
      <axis xyz="0 0 1"/>
    </joint>

    <link name="$(arg tf_prefix)/rod2_r_${wheel}">
      <visual>
        <geometry>
          <cylinder length="80" radius="0.01"/>
        </geometry>
	<material name="green" />
      </visual>
    </link>
    
    <joint name="$(arg tf_prefix)/rod2_r_${wheel}" type="fixed">
      <parent link="$(arg tf_prefix)/rod_r_${wheel}"/>
      <child link="$(arg tf_prefix)/rod2_r_${wheel}"/>
      <origin xyz="0 0 -40" rpy="0 0 0"/>
      <axis xyz="0 0 1"/>
    </joint>
    -->
  <!-- -->
  <link name="/top2">
    <inertial>
      <origin rpy="0 0 0" xyz="0 0 0"/>
      <mass value="10.21"/>
      <!-- Measured /-->
      <inertia ixx="1.267" ixy="0.086" ixz="0.078" iyy="1.089" iyz="0.150" izz="0.853"/>
      <!-- Measured /-->
    </inertial>
    <visual>
      <geometry>
        <mesh filename="package://thorvald_description/meshes/tower_modules/DUMMY-TOWER-M.stl"/>
      </geometry>
      <material name="white"/>
    </visual>
    <collision>
      <geometry>
        <mesh filename="package://thorvald_description/meshes/tower_modules/DUMMY-TOWER-M.stl"/>
      </geometry>
    </collision>
  </link>
  <joint name="/base_linktop2" type="fixed">
    <parent link="/base_link"/>
    <child link="/top2"/>
    <origin rpy="0 0 0" xyz="0.67792 0.75 0.65"/>
    <axis xyz="0 0 1"/>
  </joint>
  <link name="/leg2">
    <inertial>
      <origin rpy="0 0 0" xyz="0 0 0"/>
      <mass value="15.64"/>
      <!-- Measured /-->
      <inertia ixx="6.150" ixy="1.310" ixz="0.218" iyy="1.386" iyz="0.873" izz="6.098"/>
      <!-- Measured /-->
    </inertial>
    <visual>
      <origin rpy="0 0 0" xyz="0 0 0"/>
      <geometry>
        <mesh filename="package://thorvald_description/meshes/drive_modules/836745-5-DUMMY-RevA.stl"/>
        <!--cylinder length="${leg_length}" radius="${leg_radius}"/-->
        <!--mesh filename="package://thorvald_base/meshes/top_chassis.dae"/-->
      </geometry>
      <material name="white"/>
    </visual>
    <collision>
      <origin rpy="0 0 0" xyz="0 0 0"/>
      <geometry>
        <mesh filename="package://thorvald_description/meshes/drive_modules/836745-5-DUMMY-RevA.stl"/>
      </geometry>
    </collision>
  </link>
  <joint name="/steering2" type="continuous">
    <parent link="/base_link"/>
    <child link="/leg2"/>
    <origin rpy="0 0 0" xyz="0.67792 0.75 0.2"/>
    <axis xyz="0 0 1"/>
  </joint>
  <transmission name="steering2_tran">
    <type>transmission_interface/SimpleTransmission</type>
    <joint name="/steering2">
      <hardwareInterface>hardware_interface/EffortJointInterface</hardwareInterface>
    </joint>
    <actuator name="steering2_motor">
      <hardwareInterface>hardware_interface/EffortJointInterface</hardwareInterface>
      <mechanicalReduction>1</mechanicalReduction>
    </actuator>
  </transmission>
  <link name="/wheel2_link">
    <inertial>
      <origin rpy="0 0 0" xyz="0 0 0"/>
      <mass value="6.00"/>
      <!-- Measured /-->
      <inertia ixx="0.874" ixy="0.00" ixz="0.00" iyy="1.504" iyz="0.00" izz="0.874"/>
      <!-- Measured /-->
    </inertial>
    <visual>
      <geometry>
        <cylinder length="0.16" radius="0.2"/>
      </geometry>
      <material name="black"/>
    </visual>
    <collision>
      <geometry>
        <cylinder length="0.16" radius="0.2"/>
      </geometry>
    </collision>
  </link>
  <gazebo reference="/wheel2_link">
    <material>Gazebo/Black</material>
    <mu1 value="0.5"/>
    <mu2 value="0.5"/>
    <kp value="1000000.0"/>
    <kd value="1.0"/>
  </gazebo>
  <joint name="/wheel2" type="continuous">
    <parent link="/leg2"/>
    <child link="/wheel2_link"/>
    <origin rpy="-1.57079632679 0 0" xyz="0 0 0"/>
    <axis xyz="0 0 1"/>
    <!--dynamics damping="0" friction="0"/-->
  </joint>
  <transmission name="wheel2_tran">
    <type>transmission_interface/SimpleTransmission</type>
    <joint name="/wheel2">
      <hardwareInterface>hardware_interface/EffortJointInterface</hardwareInterface>
    </joint>
    <actuator name="wheel2_motor">
      <hardwareInterface>hardware_interface/EffortJointInterface</hardwareInterface>
      <mechanicalReduction>1</mechanicalReduction>
    </actuator>
  </transmission>
  <!-- -->
  <!--
    <link name="$(arg tf_prefix)/rod_l_${wheel}">
      <visual>
        <geometry>
          <cylinder length="20" radius="0.01"/>
        </geometry>
	<material name="red" />
      </visual>
    </link>
      
    
    <joint name="$(arg tf_prefix)/rod_l_${wheel}" type="fixed">
      <parent link="$(arg tf_prefix)/${wheel}_link"/>
      <child link="$(arg tf_prefix)/rod_l_${wheel}"/>
      <origin xyz="0 0 10" rpy="0 0 0"/>
      <axis xyz="0 0 1"/>
    </joint>

    <link name="$(arg tf_prefix)/rod_r_${wheel}">
      <visual>
        <geometry>
          <cylinder length="20" radius="0.01"/>
        </geometry>
	<material name="green" />
      </visual>
    </link>
    
    <joint name="$(arg tf_prefix)/rod_r_${wheel}" type="fixed">
      <parent link="$(arg tf_prefix)/${wheel}_link"/>
      <child link="$(arg tf_prefix)/rod_r_${wheel}"/>
      <origin xyz="0 0 -10" rpy="0 0 0"/>
      <axis xyz="0 0 1"/>
    </joint>



    <link name="$(arg tf_prefix)/rod2_l_${wheel}">
      <visual>
        <geometry>
          <cylinder length="80" radius="0.01"/>
        </geometry>
	<material name="red" />
      </visual>
    </link>

    <joint name="$(arg tf_prefix)/rod2_l_${wheel}" type="fixed">
      <parent link="$(arg tf_prefix)/rod_l_${wheel}"/>
      <child link="$(arg tf_prefix)/rod2_l_${wheel}"/>
      <origin xyz="0 0 40" rpy="0 0 0"/>
      <axis xyz="0 0 1"/>
    </joint>

    <link name="$(arg tf_prefix)/rod2_r_${wheel}">
      <visual>
        <geometry>
          <cylinder length="80" radius="0.01"/>
        </geometry>
	<material name="green" />
      </visual>
    </link>
    
    <joint name="$(arg tf_prefix)/rod2_r_${wheel}" type="fixed">
      <parent link="$(arg tf_prefix)/rod_r_${wheel}"/>
      <child link="$(arg tf_prefix)/rod2_r_${wheel}"/>
      <origin xyz="0 0 -40" rpy="0 0 0"/>
      <axis xyz="0 0 1"/>
    </joint>
    -->
  <!-- -->
  <link name="/top3">
    <inertial>
      <origin rpy="0 0 0" xyz="0 0 0"/>
      <mass value="10.21"/>
      <!-- Measured /-->
      <inertia ixx="1.267" ixy="0.086" ixz="0.078" iyy="1.089" iyz="0.150" izz="0.853"/>
      <!-- Measured /-->
    </inertial>
    <visual>
      <geometry>
        <mesh filename="package://thorvald_description/meshes/tower_modules/DUMMY-TOWER-MIRROR-M.stl"/>
      </geometry>
      <material name="white"/>
    </visual>
    <collision>
      <geometry>
        <mesh filename="package://thorvald_description/meshes/tower_modules/DUMMY-TOWER-MIRROR-M.stl"/>
      </geometry>
    </collision>
  </link>
  <joint name="/base_linktop3" type="fixed">
    <parent link="/base_link"/>
    <child link="/top3"/>
    <origin rpy="0 0 3.14159265359" xyz="-0.67792 0.75 0.65"/>
    <axis xyz="0 0 1"/>
  </joint>
  <link name="/leg3">
    <inertial>
      <origin rpy="0 0 0" xyz="0 0 0"/>
      <mass value="15.64"/>
      <!-- Measured /-->
      <inertia ixx="6.150" ixy="1.310" ixz="0.218" iyy="1.386" iyz="0.873" izz="6.098"/>
      <!-- Measured /-->
    </inertial>
    <visual>
      <origin rpy="0 0 3.14159265359" xyz="0 0 0"/>
      <geometry>
        <mesh filename="package://thorvald_description/meshes/drive_modules/836745-5-DUMMY-MIRROR-RevA.stl"/>
        <!--cylinder length="${leg_length}" radius="${leg_radius}"/-->
        <!--mesh filename="package://thorvald_base/meshes/top_chassis.dae"/-->
      </geometry>
      <material name="white"/>
    </visual>
    <collision>
      <origin rpy="0 0 3.14159265359" xyz="0 0 0"/>
      <geometry>
        <mesh filename="package://thorvald_description/meshes/drive_modules/836745-5-DUMMY-MIRROR-RevA.stl"/>
      </geometry>
    </collision>
  </link>
  <joint name="/steering3" type="continuous">
    <parent link="/base_link"/>
    <child link="/leg3"/>
    <origin rpy="0 0 0" xyz="-0.67792 0.75 0.2"/>
    <axis xyz="0 0 1"/>
  </joint>
  <transmission name="steering3_tran">
    <type>transmission_interface/SimpleTransmission</type>
    <joint name="/steering3">
      <hardwareInterface>hardware_interface/EffortJointInterface</hardwareInterface>
    </joint>
    <actuator name="steering3_motor">
      <hardwareInterface>hardware_interface/EffortJointInterface</hardwareInterface>
      <mechanicalReduction>1</mechanicalReduction>
    </actuator>
  </transmission>
  <link name="/wheel3_link">
    <inertial>
      <origin rpy="0 0 0" xyz="0 0 0"/>
      <mass value="6.00"/>
      <!-- Measured /-->
      <inertia ixx="0.874" ixy="0.00" ixz="0.00" iyy="1.504" iyz="0.00" izz="0.874"/>
      <!-- Measured /-->
    </inertial>
    <visual>
      <geometry>
        <cylinder length="0.16" radius="0.2"/>
      </geometry>
      <material name="black"/>
    </visual>
    <collision>
      <geometry>
        <cylinder length="0.16" radius="0.2"/>
      </geometry>
    </collision>
  </link>
  <gazebo reference="/wheel3_link">
    <material>Gazebo/Black</material>
    <mu1 value="0.5"/>
    <mu2 value="0.5"/>
    <kp value="1000000.0"/>
    <kd value="1.0"/>
  </gazebo>
  <joint name="/wheel3" type="continuous">
    <parent link="/leg3"/>
    <child link="/wheel3_link"/>
    <origin rpy="-1.57079632679 0 0" xyz="0 0 0"/>
    <axis xyz="0 0 1"/>
    <!--dynamics damping="0" friction="0"/-->
  </joint>
  <transmission name="wheel3_tran">
    <type>transmission_interface/SimpleTransmission</type>
    <joint name="/wheel3">
      <hardwareInterface>hardware_interface/EffortJointInterface</hardwareInterface>
    </joint>
    <actuator name="wheel3_motor">
      <hardwareInterface>hardware_interface/EffortJointInterface</hardwareInterface>
      <mechanicalReduction>1</mechanicalReduction>
    </actuator>
  </transmission>
  <!-- -->
  <!--
    <link name="$(arg tf_prefix)/rod_l_${wheel}">
      <visual>
        <geometry>
          <cylinder length="20" radius="0.01"/>
        </geometry>
	<material name="red" />
      </visual>
    </link>
      
    
    <joint name="$(arg tf_prefix)/rod_l_${wheel}" type="fixed">
      <parent link="$(arg tf_prefix)/${wheel}_link"/>
      <child link="$(arg tf_prefix)/rod_l_${wheel}"/>
      <origin xyz="0 0 10" rpy="0 0 0"/>
      <axis xyz="0 0 1"/>
    </joint>

    <link name="$(arg tf_prefix)/rod_r_${wheel}">
      <visual>
        <geometry>
          <cylinder length="20" radius="0.01"/>
        </geometry>
	<material name="green" />
      </visual>
    </link>
    
    <joint name="$(arg tf_prefix)/rod_r_${wheel}" type="fixed">
      <parent link="$(arg tf_prefix)/${wheel}_link"/>
      <child link="$(arg tf_prefix)/rod_r_${wheel}"/>
      <origin xyz="0 0 -10" rpy="0 0 0"/>
      <axis xyz="0 0 1"/>
    </joint>



    <link name="$(arg tf_prefix)/rod2_l_${wheel}">
      <visual>
        <geometry>
          <cylinder length="80" radius="0.01"/>
        </geometry>
	<material name="red" />
      </visual>
    </link>

    <joint name="$(arg tf_prefix)/rod2_l_${wheel}" type="fixed">
      <parent link="$(arg tf_prefix)/rod_l_${wheel}"/>
      <child link="$(arg tf_prefix)/rod2_l_${wheel}"/>
      <origin xyz="0 0 40" rpy="0 0 0"/>
      <axis xyz="0 0 1"/>
    </joint>

    <link name="$(arg tf_prefix)/rod2_r_${wheel}">
      <visual>
        <geometry>
          <cylinder length="80" radius="0.01"/>
        </geometry>
	<material name="green" />
      </visual>
    </link>
    
    <joint name="$(arg tf_prefix)/rod2_r_${wheel}" type="fixed">
      <parent link="$(arg tf_prefix)/rod_r_${wheel}"/>
      <child link="$(arg tf_prefix)/rod2_r_${wheel}"/>
      <origin xyz="0 0 -40" rpy="0 0 0"/>
      <axis xyz="0 0 1"/>
    </joint>
    -->
  <!-- -->
  <link name="/corner0_1">
    <inertial>
      <origin rpy="0 0 0" xyz="0 0 0"/>
      <mass value="0.915"/>
      <!-- Measured /-->
      <inertia ixx="1.0" ixy="0.0" ixz="0.0" iyy="1.0" iyz="0.0" izz="1.0"/>
      <!-- Guess /-->
    </inertial>
    <visual>
      <geometry>
        <mesh filename="package://thorvald_description/meshes/clamps/DUMMY-T-BRACKET.stl"/>
      </geometry>
      <material name="alu"/>
    </visual>
  </link>
  <link name="/corner0_2">
    <inertial>
      <origin rpy="0 0 0" xyz="0 0 0"/>
      <mass value="0.915"/>
      <!-- Measured /-->
      <inertia ixx="1.0" ixy="0.0" ixz="0.0" iyy="1.0" iyz="0.0" izz="1.0"/>
      <!-- Guess /-->
    </inertial>
    <visual>
      <geometry>
        <mesh filename="package://thorvald_description/meshes/clamps/DUMMY-T-BRACKET.stl"/>
      </geometry>
      <material name="alu"/>
    </visual>
  </link>
  <link name="/corner0">
    <inertial>
      <origin rpy="0 0 0" xyz="0 0 0"/>
      <mass value="0.915"/>
      <!-- Measured /-->
      <inertia ixx="1.0" ixy="0.0" ixz="0.0" iyy="1.0" iyz="0.0" izz="1.0"/>
      <!-- Guess /-->
    </inertial>
    <visual>
      <geometry>
        <cylinder length="0.15" radius="0.02"/>
      </geometry>
      <material name="alu"/>
    </visual>
  </link>
  <joint name="/corner0_link_1" type="fixed">
    <parent link="/corner0"/>
    <child link="/corner0_1"/>
    <origin rpy="0 0 0" xyz="0.057 0 -0.075"/>
    <axis xyz="0 0 1"/>
  </joint>
  <joint name="/corner0_link_2" type="fixed">
    <parent link="/corner0"/>
    <child link="/corner0_2"/>
    <origin rpy="0 0 0" xyz="0.057 0 0.075"/>
    <axis xyz="0 0 1"/>
  </joint>
  <link name="/corner0_3">
    <inertial>
      <origin rpy="0 0 0" xyz="0 0 0"/>
      <mass value="0.915"/>
      <!-- Measured /-->
      <inertia ixx="1.0" ixy="0.0" ixz="0.0" iyy="1.0" iyz="0.0" izz="1.0"/>
      <!-- Guess /-->
    </inertial>
    <visual>
      <geometry>
        <mesh filename="package://thorvald_description/meshes/clamps/DUMMY-SUSP.stl"/>
      </geometry>
      <material name="alu"/>
    </visual>
  </link>
  <link name="/corner0_4">
    <inertial>
      <origin rpy="0 0 0" xyz="0 0 0"/>
      <mass value="0.915"/>
      <!-- Measured /-->
      <inertia ixx="1.0" ixy="0.0" ixz="0.0" iyy="1.0" iyz="0.0" izz="1.0"/>
      <!-- Guess /-->
    </inertial>
    <visual>
      <geometry>
        <mesh filename="package://thorvald_description/meshes/clamps/DUMMY-SUSP.stl"/>
      </geometry>
      <material name="alu"/>
    </visual>
  </link>
  <joint name="/corner0_link_3" type="fixed">
    <parent link="/corner0"/>
    <child link="/corner0_3"/>
    <origin rpy="0 0.25 0" xyz="0.1 0 -0.075"/>
    <axis xyz="0 0 1"/>
  </joint>
  <joint name="/corner0_link_4" type="fixed">
    <parent link="/corner0"/>
    <child link="/corner0_4"/>
    <origin rpy="0 0.25 0" xyz="0.1 0 0.075"/>
    <axis xyz="0 0 1"/>
  </joint>
  <joint name="/corner0_link" type="fixed">
    <parent link="/base_link"/>
    <child link="/corner0"/>
    <origin rpy="0 0 -3.14159265359" xyz="-0.368 -0.75 0.68221"/>
    <axis xyz="0 0 1"/>
  </joint>
  <link name="/corner1_1">
    <inertial>
      <origin rpy="0 0 0" xyz="0 0 0"/>
      <mass value="0.915"/>
      <!-- Measured /-->
      <inertia ixx="1.0" ixy="0.0" ixz="0.0" iyy="1.0" iyz="0.0" izz="1.0"/>
      <!-- Guess /-->
    </inertial>
    <visual>
      <geometry>
        <mesh filename="package://thorvald_description/meshes/clamps/DUMMY-T-BRACKET.stl"/>
      </geometry>
      <material name="alu"/>
    </visual>
  </link>
  <link name="/corner1_2">
    <inertial>
      <origin rpy="0 0 0" xyz="0 0 0"/>
      <mass value="0.915"/>
      <!-- Measured /-->
      <inertia ixx="1.0" ixy="0.0" ixz="0.0" iyy="1.0" iyz="0.0" izz="1.0"/>
      <!-- Guess /-->
    </inertial>
    <visual>
      <geometry>
        <mesh filename="package://thorvald_description/meshes/clamps/DUMMY-T-BRACKET.stl"/>
      </geometry>
      <material name="alu"/>
    </visual>
  </link>
  <link name="/corner1">
    <inertial>
      <origin rpy="0 0 0" xyz="0 0 0"/>
      <mass value="0.915"/>
      <!-- Measured /-->
      <inertia ixx="1.0" ixy="0.0" ixz="0.0" iyy="1.0" iyz="0.0" izz="1.0"/>
      <!-- Guess /-->
    </inertial>
    <visual>
      <geometry>
        <cylinder length="0.15" radius="0.02"/>
      </geometry>
      <material name="alu"/>
    </visual>
  </link>
  <joint name="/corner1_link_1" type="fixed">
    <parent link="/corner1"/>
    <child link="/corner1_1"/>
    <origin rpy="0 0 0" xyz="0.057 0 -0.075"/>
    <axis xyz="0 0 1"/>
  </joint>
  <joint name="/corner1_link_2" type="fixed">
    <parent link="/corner1"/>
    <child link="/corner1_2"/>
    <origin rpy="0 0 0" xyz="0.057 0 0.075"/>
    <axis xyz="0 0 1"/>
  </joint>
  <link name="/corner1_3">
    <inertial>
      <origin rpy="0 0 0" xyz="0 0 0"/>
      <mass value="0.915"/>
      <!-- Measured /-->
      <inertia ixx="1.0" ixy="0.0" ixz="0.0" iyy="1.0" iyz="0.0" izz="1.0"/>
      <!-- Guess /-->
    </inertial>
    <visual>
      <geometry>
        <mesh filename="package://thorvald_description/meshes/clamps/DUMMY-SUSP.stl"/>
      </geometry>
      <material name="alu"/>
    </visual>
  </link>
  <link name="/corner1_4">
    <inertial>
      <origin rpy="0 0 0" xyz="0 0 0"/>
      <mass value="0.915"/>
      <!-- Measured /-->
      <inertia ixx="1.0" ixy="0.0" ixz="0.0" iyy="1.0" iyz="0.0" izz="1.0"/>
      <!-- Guess /-->
    </inertial>
    <visual>
      <geometry>
        <mesh filename="package://thorvald_description/meshes/clamps/DUMMY-SUSP.stl"/>
      </geometry>
      <material name="alu"/>
    </visual>
  </link>
  <joint name="/corner1_link_3" type="fixed">
    <parent link="/corner1"/>
    <child link="/corner1_3"/>
    <origin rpy="0 0.25 0" xyz="0.1 0 -0.075"/>
    <axis xyz="0 0 1"/>
  </joint>
  <joint name="/corner1_link_4" type="fixed">
    <parent link="/corner1"/>
    <child link="/corner1_4"/>
    <origin rpy="0 0.25 0" xyz="0.1 0 0.075"/>
    <axis xyz="0 0 1"/>
  </joint>
  <joint name="/corner1_link" type="fixed">
    <parent link="/base_link"/>
    <child link="/corner1"/>
    <origin rpy="0 0 0" xyz="0.368 -0.75 0.68221"/>
    <axis xyz="0 0 1"/>
  </joint>
  <link name="/corner2_1">
    <inertial>
      <origin rpy="0 0 0" xyz="0 0 0"/>
      <mass value="0.915"/>
      <!-- Measured /-->
      <inertia ixx="1.0" ixy="0.0" ixz="0.0" iyy="1.0" iyz="0.0" izz="1.0"/>
      <!-- Guess /-->
    </inertial>
    <visual>
      <geometry>
        <mesh filename="package://thorvald_description/meshes/clamps/DUMMY-T-BRACKET.stl"/>
      </geometry>
      <material name="alu"/>
    </visual>
  </link>
  <link name="/corner2_2">
    <inertial>
      <origin rpy="0 0 0" xyz="0 0 0"/>
      <mass value="0.915"/>
      <!-- Measured /-->
      <inertia ixx="1.0" ixy="0.0" ixz="0.0" iyy="1.0" iyz="0.0" izz="1.0"/>
      <!-- Guess /-->
    </inertial>
    <visual>
      <geometry>
        <mesh filename="package://thorvald_description/meshes/clamps/DUMMY-T-BRACKET.stl"/>
      </geometry>
      <material name="alu"/>
    </visual>
  </link>
  <link name="/corner2">
    <inertial>
      <origin rpy="0 0 0" xyz="0 0 0"/>
      <mass value="0.915"/>
      <!-- Measured /-->
      <inertia ixx="1.0" ixy="0.0" ixz="0.0" iyy="1.0" iyz="0.0" izz="1.0"/>
      <!-- Guess /-->
    </inertial>
    <visual>
      <geometry>
        <cylinder length="0.15" radius="0.02"/>
      </geometry>
      <material name="alu"/>
    </visual>
  </link>
  <joint name="/corner2_link_1" type="fixed">
    <parent link="/corner2"/>
    <child link="/corner2_1"/>
    <origin rpy="0 0 0" xyz="0.057 0 -0.075"/>
    <axis xyz="0 0 1"/>
  </joint>
  <joint name="/corner2_link_2" type="fixed">
    <parent link="/corner2"/>
    <child link="/corner2_2"/>
    <origin rpy="0 0 0" xyz="0.057 0 0.075"/>
    <axis xyz="0 0 1"/>
  </joint>
  <link name="/corner2_3">
    <inertial>
      <origin rpy="0 0 0" xyz="0 0 0"/>
      <mass value="0.915"/>
      <!-- Measured /-->
      <inertia ixx="1.0" ixy="0.0" ixz="0.0" iyy="1.0" iyz="0.0" izz="1.0"/>
      <!-- Guess /-->
    </inertial>
    <visual>
      <geometry>
        <mesh filename="package://thorvald_description/meshes/clamps/DUMMY-SUSP.stl"/>
      </geometry>
      <material name="alu"/>
    </visual>
  </link>
  <link name="/corner2_4">
    <inertial>
      <origin rpy="0 0 0" xyz="0 0 0"/>
      <mass value="0.915"/>
      <!-- Measured /-->
      <inertia ixx="1.0" ixy="0.0" ixz="0.0" iyy="1.0" iyz="0.0" izz="1.0"/>
      <!-- Guess /-->
    </inertial>
    <visual>
      <geometry>
        <mesh filename="package://thorvald_description/meshes/clamps/DUMMY-SUSP.stl"/>
      </geometry>
      <material name="alu"/>
    </visual>
  </link>
  <joint name="/corner2_link_3" type="fixed">
    <parent link="/corner2"/>
    <child link="/corner2_3"/>
    <origin rpy="0 0.25 0" xyz="0.1 0 -0.075"/>
    <axis xyz="0 0 1"/>
  </joint>
  <joint name="/corner2_link_4" type="fixed">
    <parent link="/corner2"/>
    <child link="/corner2_4"/>
    <origin rpy="0 0.25 0" xyz="0.1 0 0.075"/>
    <axis xyz="0 0 1"/>
  </joint>
  <joint name="/corner2_link" type="fixed">
    <parent link="/base_link"/>
    <child link="/corner2"/>
    <origin rpy="0 0 0" xyz="0.368 0.75 0.68221"/>
    <axis xyz="0 0 1"/>
  </joint>
  <link name="/corner3_1">
    <inertial>
      <origin rpy="0 0 0" xyz="0 0 0"/>
      <mass value="0.915"/>
      <!-- Measured /-->
      <inertia ixx="1.0" ixy="0.0" ixz="0.0" iyy="1.0" iyz="0.0" izz="1.0"/>
      <!-- Guess /-->
    </inertial>
    <visual>
      <geometry>
        <mesh filename="package://thorvald_description/meshes/clamps/DUMMY-T-BRACKET.stl"/>
      </geometry>
      <material name="alu"/>
    </visual>
  </link>
  <link name="/corner3_2">
    <inertial>
      <origin rpy="0 0 0" xyz="0 0 0"/>
      <mass value="0.915"/>
      <!-- Measured /-->
      <inertia ixx="1.0" ixy="0.0" ixz="0.0" iyy="1.0" iyz="0.0" izz="1.0"/>
      <!-- Guess /-->
    </inertial>
    <visual>
      <geometry>
        <mesh filename="package://thorvald_description/meshes/clamps/DUMMY-T-BRACKET.stl"/>
      </geometry>
      <material name="alu"/>
    </visual>
  </link>
  <link name="/corner3">
    <inertial>
      <origin rpy="0 0 0" xyz="0 0 0"/>
      <mass value="0.915"/>
      <!-- Measured /-->
      <inertia ixx="1.0" ixy="0.0" ixz="0.0" iyy="1.0" iyz="0.0" izz="1.0"/>
      <!-- Guess /-->
    </inertial>
    <visual>
      <geometry>
        <cylinder length="0.15" radius="0.02"/>
      </geometry>
      <material name="alu"/>
    </visual>
  </link>
  <joint name="/corner3_link_1" type="fixed">
    <parent link="/corner3"/>
    <child link="/corner3_1"/>
    <origin rpy="0 0 0" xyz="0.057 0 -0.075"/>
    <axis xyz="0 0 1"/>
  </joint>
  <joint name="/corner3_link_2" type="fixed">
    <parent link="/corner3"/>
    <child link="/corner3_2"/>
    <origin rpy="0 0 0" xyz="0.057 0 0.075"/>
    <axis xyz="0 0 1"/>
  </joint>
  <link name="/corner3_3">
    <inertial>
      <origin rpy="0 0 0" xyz="0 0 0"/>
      <mass value="0.915"/>
      <!-- Measured /-->
      <inertia ixx="1.0" ixy="0.0" ixz="0.0" iyy="1.0" iyz="0.0" izz="1.0"/>
      <!-- Guess /-->
    </inertial>
    <visual>
      <geometry>
        <mesh filename="package://thorvald_description/meshes/clamps/DUMMY-SUSP.stl"/>
      </geometry>
      <material name="alu"/>
    </visual>
  </link>
  <link name="/corner3_4">
    <inertial>
      <origin rpy="0 0 0" xyz="0 0 0"/>
      <mass value="0.915"/>
      <!-- Measured /-->
      <inertia ixx="1.0" ixy="0.0" ixz="0.0" iyy="1.0" iyz="0.0" izz="1.0"/>
      <!-- Guess /-->
    </inertial>
    <visual>
      <geometry>
        <mesh filename="package://thorvald_description/meshes/clamps/DUMMY-SUSP.stl"/>
      </geometry>
      <material name="alu"/>
    </visual>
  </link>
  <joint name="/corner3_link_3" type="fixed">
    <parent link="/corner3"/>
    <child link="/corner3_3"/>
    <origin rpy="0 0.25 0" xyz="0.1 0 -0.075"/>
    <axis xyz="0 0 1"/>
  </joint>
  <joint name="/corner3_link_4" type="fixed">
    <parent link="/corner3"/>
    <child link="/corner3_4"/>
    <origin rpy="0 0.25 0" xyz="0.1 0 0.075"/>
    <axis xyz="0 0 1"/>
  </joint>
  <joint name="/corner3_link" type="fixed">
    <parent link="/base_link"/>
    <child link="/corner3"/>
    <origin rpy="0 0 -3.14159265359" xyz="-0.368 0.75 0.68221"/>
    <axis xyz="0 0 1"/>
  </joint>
  <link name="/pipe0_1">
    <inertial>
      <origin rpy="0 0 0" xyz="0 0 0"/>
      <mass value="1.0"/>
      <!-- guess /-->
      <inertia ixx="1.0" ixy="0.0" ixz="0.0" iyy="1.0" iyz="0.0" izz="1.0"/>
      <!-- guess /-->
    </inertial>
    <visual>
      <geometry>
        <cylinder length="0.85" radius="0.02"/>
      </geometry>
      <material name="alu"/>
    </visual>
    <collision>
      <geometry>
        <cylinder length="0.85" radius="0.02"/>
      </geometry>
    </collision>
  </link>
  <link name="/pipe0_2">
    <inertial>
      <origin rpy="0 0 0" xyz="0 0 0"/>
      <mass value="1.0"/>
      <!-- guess /-->
      <inertia ixx="1.0" ixy="0.0" ixz="0.0" iyy="1.0" iyz="0.0" izz="1.0"/>
      <!-- guess /-->
    </inertial>
    <visual>
      <geometry>
        <cylinder length="0.85" radius="0.02"/>
      </geometry>
      <material name="alu"/>
    </visual>
    <collision>
      <geometry>
        <cylinder length="0.85" radius="0.02"/>
      </geometry>
    </collision>
  </link>
  <joint name="/pipe0_link_1" type="fixed">
    <parent link="/base_link"/>
    <child link="/pipe0_1"/>
    <origin rpy="1.57079632679 0 -1.57079632679" xyz="0.0 -0.75 0.60721"/>
    <axis xyz="0 0 1"/>
  </joint>
  <joint name="/pipe0_link_2" type="fixed">
    <parent link="/base_link"/>
    <child link="/pipe0_2"/>
    <origin rpy="1.57079632679 0 -1.57079632679" xyz="0.0 -0.75 0.75721"/>
    <axis xyz="0 0 1"/>
  </joint>
  <link name="/pipe1_1">
    <inertial>
      <origin rpy="0 0 0" xyz="0 0 0"/>
      <mass value="1.0"/>
      <!-- guess /-->
      <inertia ixx="1.0" ixy="0.0" ixz="0.0" iyy="1.0" iyz="0.0" izz="1.0"/>
      <!-- guess /-->
    </inertial>
    <visual>
      <geometry>
        <cylinder length="1.5" radius="0.02"/>
      </geometry>
      <material name="alu"/>
    </visual>
    <collision>
      <geometry>
        <cylinder length="1.5" radius="0.02"/>
      </geometry>
    </collision>
  </link>
  <link name="/pipe1_2">
    <inertial>
      <origin rpy="0 0 0" xyz="0 0 0"/>
      <mass value="1.0"/>
      <!-- guess /-->
      <inertia ixx="1.0" ixy="0.0" ixz="0.0" iyy="1.0" iyz="0.0" izz="1.0"/>
      <!-- guess /-->
    </inertial>
    <visual>
      <geometry>
        <cylinder length="1.5" radius="0.02"/>
      </geometry>
      <material name="alu"/>
    </visual>
    <collision>
      <geometry>
        <cylinder length="1.5" radius="0.02"/>
      </geometry>
    </collision>
  </link>
  <joint name="/pipe1_link_1" type="fixed">
    <parent link="/base_link"/>
    <child link="/pipe1_1"/>
    <origin rpy="1.57079632679 0 0.0" xyz="0.425 0.0 0.60721"/>
    <axis xyz="0 0 1"/>
  </joint>
  <joint name="/pipe1_link_2" type="fixed">
    <parent link="/base_link"/>
    <child link="/pipe1_2"/>
    <origin rpy="1.57079632679 0 0.0" xyz="0.425 0.0 0.75721"/>
    <axis xyz="0 0 1"/>
  </joint>
  <link name="/pipe2_1">
    <inertial>
      <origin rpy="0 0 0" xyz="0 0 0"/>
      <mass value="1.0"/>
      <!-- guess /-->
      <inertia ixx="1.0" ixy="0.0" ixz="0.0" iyy="1.0" iyz="0.0" izz="1.0"/>
      <!-- guess /-->
    </inertial>
    <visual>
      <geometry>
        <cylinder length="0.85" radius="0.02"/>
      </geometry>
      <material name="alu"/>
    </visual>
    <collision>
      <geometry>
        <cylinder length="0.85" radius="0.02"/>
      </geometry>
    </collision>
  </link>
  <link name="/pipe2_2">
    <inertial>
      <origin rpy="0 0 0" xyz="0 0 0"/>
      <mass value="1.0"/>
      <!-- guess /-->
      <inertia ixx="1.0" ixy="0.0" ixz="0.0" iyy="1.0" iyz="0.0" izz="1.0"/>
      <!-- guess /-->
    </inertial>
    <visual>
      <geometry>
        <cylinder length="0.85" radius="0.02"/>
      </geometry>
      <material name="alu"/>
    </visual>
    <collision>
      <geometry>
        <cylinder length="0.85" radius="0.02"/>
      </geometry>
    </collision>
  </link>
  <joint name="/pipe2_link_1" type="fixed">
    <parent link="/base_link"/>
    <child link="/pipe2_1"/>
    <origin rpy="1.57079632679 0 1.57079632679" xyz="0.0 0.75 0.60721"/>
    <axis xyz="0 0 1"/>
  </joint>
  <joint name="/pipe2_link_2" type="fixed">
    <parent link="/base_link"/>
    <child link="/pipe2_2"/>
    <origin rpy="1.57079632679 0 1.57079632679" xyz="0.0 0.75 0.75721"/>
    <axis xyz="0 0 1"/>
  </joint>
  <link name="/pipe3_1">
    <inertial>
      <origin rpy="0 0 0" xyz="0 0 0"/>
      <mass value="1.0"/>
      <!-- guess /-->
      <inertia ixx="1.0" ixy="0.0" ixz="0.0" iyy="1.0" iyz="0.0" izz="1.0"/>
      <!-- guess /-->
    </inertial>
    <visual>
      <geometry>
        <cylinder length="1.5" radius="0.02"/>
      </geometry>
      <material name="alu"/>
    </visual>
    <collision>
      <geometry>
        <cylinder length="1.5" radius="0.02"/>
      </geometry>
    </collision>
  </link>
  <link name="/pipe3_2">
    <inertial>
      <origin rpy="0 0 0" xyz="0 0 0"/>
      <mass value="1.0"/>
      <!-- guess /-->
      <inertia ixx="1.0" ixy="0.0" ixz="0.0" iyy="1.0" iyz="0.0" izz="1.0"/>
      <!-- guess /-->
    </inertial>
    <visual>
      <geometry>
        <cylinder length="1.5" radius="0.02"/>
      </geometry>
      <material name="alu"/>
    </visual>
    <collision>
      <geometry>
        <cylinder length="1.5" radius="0.02"/>
      </geometry>
    </collision>
  </link>
  <joint name="/pipe3_link_1" type="fixed">
    <parent link="/base_link"/>
    <child link="/pipe3_1"/>
    <origin rpy="1.57079632679 0 -3.14159265359" xyz="-0.425 0.0 0.60721"/>
    <axis xyz="0 0 1"/>
  </joint>
  <joint name="/pipe3_link_2" type="fixed">
    <parent link="/base_link"/>
    <child link="/pipe3_2"/>
    <origin rpy="1.57079632679 0 -3.14159265359" xyz="-0.425 0.0 0.75721"/>
    <axis xyz="0 0 1"/>
  </joint>
  <link name="/pipe4_1">
    <inertial>
      <origin rpy="0 0 0" xyz="0 0 0"/>
      <mass value="1.0"/>
      <!-- guess /-->
      <inertia ixx="1.0" ixy="0.0" ixz="0.0" iyy="1.0" iyz="0.0" izz="1.0"/>
      <!-- guess /-->
    </inertial>
    <visual>
      <geometry>
        <cylinder length="1.72409396496" radius="0.02"/>
      </geometry>
      <material name="alu"/>
    </visual>
    <collision>
      <geometry>
        <cylinder length="1.72409396496" radius="0.02"/>
      </geometry>
    </collision>
  </link>
  <link name="/pipe4_2">
    <inertial>
      <origin rpy="0 0 0" xyz="0 0 0"/>
      <mass value="1.0"/>
      <!-- guess /-->
      <inertia ixx="1.0" ixy="0.0" ixz="0.0" iyy="1.0" iyz="0.0" izz="1.0"/>
      <!-- guess /-->
    </inertial>
    <visual>
      <geometry>
        <cylinder length="1.72409396496" radius="0.02"/>
      </geometry>
      <material name="alu"/>
    </visual>
    <collision>
      <geometry>
        <cylinder length="1.72409396496" radius="0.02"/>
      </geometry>
    </collision>
  </link>
  <joint name="/pipe4_link_1" type="fixed">
    <parent link="/base_link"/>
    <child link="/pipe4_1"/>
    <origin rpy="1.57079632679 0 -0.515549007459" xyz="0.0 0.0 0.60721"/>
    <axis xyz="0 0 1"/>
  </joint>
  <joint name="/pipe4_link_2" type="fixed">
    <parent link="/base_link"/>
    <child link="/pipe4_2"/>
    <origin rpy="1.57079632679 0 -0.515549007459" xyz="0.0 0.0 0.75721"/>
    <axis xyz="0 0 1"/>
  </joint>
  <link name="/bat0">
    <inertial>
      <origin rpy="0 0 0" xyz="0 0 -0.25"/>
      <mass value="12.88"/>
      <!-- measured /-->
      <inertia ixx="11.412" ixy="-0.004" ixz="-0.007" iyy="14.850" iyz="0.806" izz="5.588"/>
      <!-- measured /-->
    </inertial>
    <visual>
      <origin rpy="0 0 0" xyz="0 0 0"/>
      <geometry>
        <mesh filename="package://thorvald_description/meshes/bat_enc_modules/836586-1-DUMMY-RevA.stl"/>
      </geometry>
      <material name="white"/>
    </visual>
    <collision>
      <geometry>
        <mesh filename="package://thorvald_description/meshes/bat_enc_modules/836586-1-DUMMY-RevA.stl"/>
      </geometry>
    </collision>
  </link>
  <joint name="/bat0_joint" type="fixed">
    <parent link="/base_link"/>
    <child link="/bat0"/>
    <origin rpy="0 0 3.14159265359" xyz="0.0 0.75 0.75721"/>
    <axis xyz="0 0 1"/>
  </joint>
  <link name="/bat1">
    <inertial>
      <origin rpy="0 0 0" xyz="0 0 -0.25"/>
      <mass value="12.88"/>
      <!-- measured /-->
      <inertia ixx="11.412" ixy="-0.004" ixz="-0.007" iyy="14.850" iyz="0.806" izz="5.588"/>
      <!-- measured /-->
    </inertial>
    <visual>
      <origin rpy="0 0 0" xyz="0 0 0"/>
      <geometry>
        <mesh filename="package://thorvald_description/meshes/bat_enc_modules/836586-1-DUMMY-RevA.stl"/>
      </geometry>
      <material name="white"/>
    </visual>
    <collision>
      <geometry>
        <mesh filename="package://thorvald_description/meshes/bat_enc_modules/836586-1-DUMMY-RevA.stl"/>
      </geometry>
    </collision>
  </link>
  <joint name="/bat1_joint" type="fixed">
    <parent link="/base_link"/>
    <child link="/bat1"/>
    <origin rpy="0 0 0" xyz="0.0 -0.75 0.75721"/>
    <axis xyz="0 0 1"/>
  </joint>
  <link name="/uvtun_frame">
    <inertial>
      <origin rpy="0 0 0" xyz="0 0 0"/>
      <mass value="1"/>
      <inertia ixx="1.0" ixy="0.0" ixz="0.0" iyy="1.0" iyz="0.0" izz="1.0"/>
    </inertial>
    <visual>
      <geometry>
        <mesh filename="package://thorvald_description/meshes/uv_frame/uv_arc.STL"/>
      </geometry>
      <material name="whiter">
        <color rgba="1 1 1 1"/>
      </material>
    </visual>
  </link>
  <joint name="/base_uvtun_frame" type="fixed">
    <parent link="/base_link"/>
    <child link="/uvtun_frame"/>
    <origin rpy="1.57079632679 0 1.57079632679" xyz="-0.525 -0.66 0.5"/>
  </joint>
  <!-- GPS Sensors-->
  <link name="gps_front">
    <visual>
      <material name="sept_color">
        <color rgba="1 0.8 0 1"/>
      </material>
      <geometry>
        <cylinder length="0.05" radius="0.10"/>
      </geometry>
    </visual>
  </link>
  <link name="gps_back">
    <visual>
      <material name="sept_color">
        <color rgba="1 0.8 0 1"/>
      </material>
      <geometry>
        <cylinder length="0.05" radius="0.10"/>
      </geometry>
    </visual>
  </link>
  <joint name="/gps_back" type="fixed">
    <parent link="/base_link"/>
    <child link="gps_back"/>
    <origin rpy="0 0 0" xyz="-0.51 0 2.1"/>
  </joint>
  <joint name="/gps_front" type="fixed">
    <parent link="/base_link"/>
    <child link="gps_front"/>
    <origin rpy="0 0 0" xyz="0.51 0 2.1"/>
  </joint>
  <gazebo>
    <plugin filename="libhector_gazebo_ros_gps.so" name="gazebo_ros_gps">
      <alwaysOn>1</alwaysOn>
      <updateRate>4.0</updateRate>
      <bodyName>gps_front</bodyName>
      <frameId>front_gps</frameId>
      <topicName>gps_front/fix</topicName>
      <velocityTopicName>gps_front/fix_velocity</velocityTopicName>
      <drift>5.0 5.0 5.0</drift>
      <gaussianNoise>0.1 0.1 0.1</gaussianNoise>
      <velocityDrift>0 0 0</velocityDrift>
      <velocityGaussianNoise>0.1 0.1 0.1</velocityGaussianNoise>
    </plugin>
  </gazebo>
  <gazebo>
    <plugin filename="libhector_gazebo_ros_gps.so" name="gazebo_ros_gps">
      <alwaysOn>1</alwaysOn>
      <updateRate>4.0</updateRate>
      <bodyName>gps_back</bodyName>
      <frameId>back_gps</frameId>
      <topicName>gps_back/fix</topicName>
      <velocityTopicName>gps_back/fix_velocity</velocityTopicName>
      <drift>5.0 5.0 5.0</drift>
      <gaussianNoise>0.1 0.1 0.1</gaussianNoise>
      <velocityDrift>0 0 0</velocityDrift>
      <velocityGaussianNoise>0.1 0.1 0.1</velocityGaussianNoise>
    </plugin>
  </gazebo>
  <!--Laser Sensors-->
  <link name="/hokuyo_front">
    <collision>
      <origin rpy="0 0 0" xyz="0 0 0"/>
      <geometry>
        <box size="0.1 0.1 0.1"/>
      </geometry>
    </collision>
    <visual>
      <origin rpy="0 0 0" xyz="0 0 0"/>
      <geometry>
        <mesh filename="package://thorvald_description/meshes/hokuyo/hokuyo.dae"/>
      </geometry>
    </visual>
    <inertial>
      <mass value="1e-5"/>
      <origin rpy="0 0 0" xyz="0 0 0"/>
      <inertia ixx="1e-6" ixy="0" ixz="0" iyy="1e-6" iyz="0" izz="1e-6"/>
    </inertial>
  </link>
  <link name="/hokuyo_back">
    <collision>
      <origin rpy="0 0 0" xyz="0 0 0"/>
      <geometry>
        <box size="0.1 0.1 0.1"/>
      </geometry>
    </collision>
    <visual>
      <origin rpy="0 0 0" xyz="0 0 0"/>
      <geometry>
        <mesh filename="package://thorvald_description/meshes/hokuyo/hokuyo.dae"/>
      </geometry>
    </visual>
    <inertial>
      <mass value="1e-5"/>
      <origin rpy="0 0 0" xyz="0 0 0"/>
      <inertia ixx="1e-6" ixy="0" ixz="0" iyy="1e-6" iyz="0" izz="1e-6"/>
    </inertial>
  </link>
  <joint name="base_sens_hokuyo_front" type="fixed">
    <parent link="/top1"/>
    <child link="/hokuyo_front"/>
    <axis xyz="0 1 0"/>
    <origin rpy="0.0 0.0 -0.79" xyz="0.172 -0.152 -0.034"/>
  </joint>
  <joint name="base_sens_hokuyo_back" type="fixed">
    <parent link="/top3"/>
    <child link="/hokuyo_back"/>
    <axis xyz="0 1 0"/>
    <origin rpy="0.0 0.0 -0.79" xyz="0.172 -0.152 -0.034"/>
  </joint>
  <gazebo reference="/hokuyo_front">
    <sensor name="_head_hokuyo_front_sensor" type="ray">
      <pose>0 0 0 0 0 0</pose>
      <visualize>true</visualize>
      <update_rate>40</update_rate>
      <always_on>1</always_on>
      <ray>
        <scan>
          <horizontal>
            <samples>720</samples>
            <resolution>1</resolution>
            <min_angle>-2.18</min_angle>
            <max_angle>2.36</max_angle>
          </horizontal>
        </scan>
        <range>
          <min>0.10</min>
          <max>30.0</max>
          <resolution>0.01</resolution>
        </range>
        <noise>
          <type>gaussian</type>
          <!-- Noise parameters based on published spec for Hokuyo laser
               achieving "+-30mm" accuracy at range < 10m.  A mean of 0.0m and
               stddev of 0.01m will put 99.7% of samples within 0.03m of the true
               reading. -->
          <mean>0.0</mean>
          <stddev>0.01</stddev>
        </noise>
      </ray>
      <plugin filename="libgazebo_ros_laser.so" name="_hokuyo_front_node">
        <topicName>scan_front</topicName>
        <frameName>hokuyo_front</frameName>
      </plugin>
    </sensor>
  </gazebo>
  <gazebo reference="/hokuyo_back">
    <sensor name="_head_hokuyo_back_sensor" type="ray">
      <pose>0 0 0 0 0 0</pose>
      <visualize>true</visualize>
      <update_rate>40</update_rate>
      <always_on>1</always_on>
      <ray>
        <scan>
          <horizontal>
            <samples>720</samples>
            <resolution>1</resolution>
            <min_angle>-2.18</min_angle>
            <max_angle>2.36</max_angle>
          </horizontal>
        </scan>
        <range>
          <min>0.10</min>
          <max>30.0</max>
          <resolution>0.01</resolution>
        </range>
        <noise>
          <type>gaussian</type>
          <!-- Noise parameters based on published spec for Hokuyo laser
               achieving "+-30mm" accuracy at range < 10m.  A mean of 0.0m and
               stddev of 0.01m will put 99.7% of samples within 0.03m of the true
               reading. -->
          <mean>0.0</mean>
          <stddev>0.01</stddev>
        </noise>
      </ray>
      <plugin filename="libgazebo_ros_laser.so" name="_hokuyo_back_node">
        <topicName>scan_back</topicName>
        <frameName>hokuyo_back</frameName>
      </plugin>
    </sensor>
  </gazebo>
  <!-- Define link1 of 3dof Manip -->
  <link name="/Plink1">
    <inertial>
      <origin rpy="0 0 0" xyz="0 0 0"/>
      <mass value="1"/>
      <inertia ixx="1.0" ixy="0.0" ixz="0.0" iyy="1.0" iyz="0.0" izz="1.0"/>
    </inertial>
    <visual>
      <geometry>
        <mesh filename="package://graspberry_description/scara_arm/meshes/Plink1.stl"/>
      </geometry>
      <material name="whiter">
        <color rgba="1 1 1 1"/>
      </material>
    </visual>
  </link>
  <gazebo reference="/Plink1">
    <material>Gazebo/White</material>
  </gazebo>
  <joint name="/uvtun_frame_Plink1" type="fixed">
    <parent link="/uvtun_frame"/>
    <child link="/Plink1"/>
    <origin rpy="1.57079632679 0 0" xyz="0.09 0.6 0.53"/>
    <!-- xyz="0.03325 0.6 0.669" -->
  </joint>
  <!-- Define Transformation from parent uv_tun to child Plink1 frame -->
  <!-- Define plate of 3dof Manip -->
  <link name="/arm_plate">
    <inertial>
      <origin rpy="0 0 0" xyz="0 0 0"/>
      <mass value="1"/>
      <inertia ixx="1.0" ixy="0.0" ixz="0.0" iyy="1.0" iyz="0.0" izz="1.0"/>
    </inertial>
    <visual>
      <geometry>
        <mesh filename="package://graspberry_description/scara_arm/meshes/plate.stl"/>
      </geometry>
      <material name="whiter">
        <color rgba="1 1 1 1"/>
      </material>
    </visual>
  </link>
  <gazebo reference="/arm_plate">
    <material>Gazebo/White</material>
  </gazebo>
  <joint name="/Plink1_plate" type="prismatic">
    <parent link="/Plink1"/>
    <child link="/arm_plate"/>
    <origin rpy="3.14159265359 0 0" xyz="0.04375 0 0"/>
    <!-- 0.04375 0 -0.1735 -->
    <axis xyz="0 0 1"/>
    <limit effort="100" lower="0" upper="0.51" velocity="1"/>
  </joint>
  <transmission name="tran10">
    <type>transmission_interface/SimpleTransmission</type>
    <joint name="/Plink1_plate">
      <hardwareInterface>hardware_interface/EffortJointInterface</hardwareInterface>
    </joint>
    <actuator name="/prismatic_arm_act">
      <hardwareInterface>hardware_interface/EffortJointInterface</hardwareInterface>
      <mechanicalReduction>1</mechanicalReduction>
    </actuator>
  </transmission>
  <!-- Define link2 of 3dof Manip -->
  <link name="/R1link2">
    <inertial>
      <origin rpy="0 0 0" xyz="0 0 0"/>
      <mass value="1"/>
      <inertia ixx="1.0" ixy="0.0" ixz="0.0" iyy="1.0" iyz="0.0" izz="1.0"/>
    </inertial>
    <visual>
      <geometry>
        <mesh filename="package://graspberry_description/scara_arm/meshes/R1link2.stl"/>
      </geometry>
      <material name="whiter">
        <color rgba="1 1 1 1"/>
      </material>
    </visual>
  </link>
  <gazebo reference="/R1link2">
    <material>Gazebo/White</material>
  </gazebo>
  <joint name="/plate_R1link2" type="revolute">
    <parent link="/arm_plate"/>
    <child link="/R1link2"/>
    <origin rpy="0 0 0" xyz="0.06075 -0.13025 0"/>
    <!-- 0 0 -${pi/6} -->
    <axis xyz="0 0 1"/>
    <limit effort="100" lower="0" upper="-3.14" velocity="1"/>
  </joint>
  <transmission name="tran02">
    <type>transmission_interface/SimpleTransmission</type>
    <joint name="/plate_R1link2">
      <hardwareInterface>hardware_interface/EffortJointInterface</hardwareInterface>
    </joint>
    <actuator name="/plate_R1link2_act">
      <hardwareInterface>hardware_interface/EffortJointInterface</hardwareInterface>
      <mechanicalReduction>1</mechanicalReduction>
    </actuator>
  </transmission>
  <!-- Define Transformation from parent Plink1 to child R1link2 frame -->
  <!-- Define link3 of 3dof Manip -->
  <link name="/R2link3">
    <inertial>
      <origin rpy="0 0 0" xyz="0 0 0"/>
      <mass value="1"/>
      <inertia ixx="1.0" ixy="0.0" ixz="0.0" iyy="1.0" iyz="0.0" izz="1.0"/>
    </inertial>
    <visual>
      <geometry>
        <mesh filename="package://graspberry_description/scara_arm/meshes/R2link3.STL"/>
      </geometry>
      <material name="whiter">
        <color rgba="1 1 1 1"/>
      </material>
    </visual>
  </link>
  <gazebo reference="/R2link3">
    <material>Gazebo/White</material>
  </gazebo>
  <joint name="/R1link2_R2link3" type="revolute">
    <parent link="/R1link2"/>
    <child link="/R2link3"/>
    <origin rpy="0 0 0.523598775598" xyz="0.014 0.265 0"/>
    <!-- 0 0 -${pi/2} -->
    <axis xyz="0 0 1"/>
    <limit effort="100" lower="0" upper="3.14" velocity="1"/>
  </joint>
  <transmission name="tran23">
    <type>transmission_interface/SimpleTransmission</type>
    <joint name="/R1link2_R2link3">
      <hardwareInterface>hardware_interface/EffortJointInterface</hardwareInterface>
    </joint>
    <actuator name="/R1link2_R2link3_act">
      <hardwareInterface>hardware_interface/EffortJointInterface</hardwareInterface>
      <mechanicalReduction>1</mechanicalReduction>
    </actuator>
  </transmission>
  <!-- Define Transformation from parent R1link2 to child R2link3 frame -->
  <!-- Add 2nd arm on opposite side f reference frame of the uvtun -->
  <!-- Define link1 of 3dof Manip -->
  <link name="/Plink1M">
    <inertial>
      <origin rpy="0 0 0" xyz="0 0 0"/>
      <mass value="1"/>
      <inertia ixx="1.0" ixy="0.0" ixz="0.0" iyy="1.0" iyz="0.0" izz="1.0"/>
    </inertial>
    <visual>
      <geometry>
        <mesh filename="package://graspberry_description/scara_arm/meshes/Plink1-Mirror.stl"/>
      </geometry>
      <material name="whiter">
        <color rgba="1 1 1 1"/>
      </material>
    </visual>
  </link>
  <gazebo reference="/Plink1M">
    <material>Gazebo/White</material>
  </gazebo>
  <joint name="/uvtun_frame_Plink1M" type="fixed">
    <parent link="/uvtun_frame"/>
    <child link="/Plink1M"/>
    <origin rpy="1.5707 3.14159265359 0" xyz="1.2305 0.6 0.53"/>
    <!-- 1.23375 0.6 0.669 -->
  </joint>
  <!-- Define Transformation from parent uv_tun to child Plink1 frame -->
  <!-- Define plate of 3dof Manip -->
  <link name="/arm_plateM">
    <inertial>
      <origin rpy="0 0 0" xyz="0 0 0"/>
      <mass value="1"/>
      <inertia ixx="1.0" ixy="0.0" ixz="0.0" iyy="1.0" iyz="0.0" izz="1.0"/>
    </inertial>
    <visual>
      <geometry>
        <mesh filename="package://graspberry_description/scara_arm/meshes/plate-Mirror.stl"/>
      </geometry>
      <material name="whiter">
        <color rgba="1 1 1 1"/>
      </material>
    </visual>
  </link>
  <gazebo reference="/arm_plate">
    <material>Gazebo/White</material>
  </gazebo>
  <joint name="/Plink1_plateM" type="prismatic">
    <parent link="/Plink1M"/>
    <child link="/arm_plateM"/>
    <origin rpy="3.14159265359 0 0" xyz="0.04375 0 0"/>
    <axis xyz="0 0 1"/>
    <limit effort="100" lower="0" upper="0.51" velocity="1"/>
  </joint>
  <transmission name="tran10M">
    <type>transmission_interface/SimpleTransmission</type>
    <joint name="/Plink1_plateM">
      <hardwareInterface>hardware_interface/EffortJointInterface</hardwareInterface>
    </joint>
    <actuator name="/prismatic_arm_actM">
      <hardwareInterface>hardware_interface/EffortJointInterface</hardwareInterface>
      <mechanicalReduction>1</mechanicalReduction>
    </actuator>
  </transmission>
  <!-- Define link2 of 3dof Manip -->
  <link name="/R1link2M">
    <inertial>
      <origin rpy="0 0 0" xyz="0 0 0"/>
      <mass value="1"/>
      <inertia ixx="1.0" ixy="0.0" ixz="0.0" iyy="1.0" iyz="0.0" izz="1.0"/>
    </inertial>
    <visual>
      <geometry>
        <mesh filename="package://graspberry_description/scara_arm/meshes/R1link2-Mirror.stl"/>
      </geometry>
      <material name="whiter">
        <color rgba="1 1 1 1"/>
      </material>
    </visual>
  </link>
  <gazebo reference="/R1link2M">
    <material>Gazebo/White</material>
  </gazebo>
  <joint name="/plate_R1link2M" type="revolute">
    <parent link="/arm_plateM"/>
    <child link="/R1link2M"/>
    <origin rpy="0 0 0" xyz="0.06075 -0.13025 0"/>
    <axis xyz="0 0 1"/>
    <limit effort="100" lower="-1.5707" upper="1.5707" velocity="1"/>
  </joint>
  <transmission name="tran02M">
    <type>transmission_interface/SimpleTransmission</type>
    <joint name="/plate_R1link2M">
      <hardwareInterface>hardware_interface/EffortJointInterface</hardwareInterface>
    </joint>
    <actuator name="/plate_R1link2M_act">
      <hardwareInterface>hardware_interface/EffortJointInterface</hardwareInterface>
      <mechanicalReduction>1</mechanicalReduction>
    </actuator>
  </transmission>
  <!-- Define Transformation from parent Plink1 to child R1link2 frame -->
  <!-- Define link3 of 3dof Manip -->
  <link name="/R2link3M">
    <inertial>
      <origin rpy="0 0 0" xyz="0 0 0"/>
      <mass value="1"/>
      <inertia ixx="1.0" ixy="0.0" ixz="0.0" iyy="1.0" iyz="0.0" izz="1.0"/>
    </inertial>
    <visual>
      <geometry>
        <mesh filename="package://graspberry_description/scara_arm/meshes/R2link3-Mirror.STL"/>
      </geometry>
      <material name="whiter">
        <color rgba="1 1 1 1"/>
      </material>
    </visual>
  </link>
  <gazebo reference="/R2link3M">
    <material>Gazebo/White</material>
  </gazebo>
  <joint name="/R1link2_R2link3M" type="revolute">
    <parent link="/R1link2M"/>
    <child link="/R2link3M"/>
    <origin rpy="0 0 0.523598775598" xyz="0.014 0.265 0"/>
    <axis xyz="0 0 1"/>
    <limit effort="100" lower="0" upper="-3.14" velocity="1"/>
  </joint>
  <transmission name="tran23M">
    <type>transmission_interface/SimpleTransmission</type>
    <joint name="/R1link2_R2link3M">
      <hardwareInterface>hardware_interface/EffortJointInterface</hardwareInterface>
    </joint>
    <actuator name="/R1link2_R2link3M_act">
      <hardwareInterface>hardware_interface/EffortJointInterface</hardwareInterface>
      <mechanicalReduction>1</mechanicalReduction>
    </actuator>
  </transmission>
  <!-- Define Transformation from parent R1link2 to child R2link3 frame -->
  <gazebo>
    <plugin filename="libgazebo_ros_control.so" name="gazebo_ros_control">
      <!-- libgazebo_ros_control.so is generated in devel/lib after compilation -->
      <robotSimType>gazebo_ros_control/DefaultRobotHWSim</robotSimType>
      <legacyModeNS>true</legacyModeNS>
      <robotNamespace>/scara_arm</robotNamespace>
    </plugin>
  </gazebo>
</robot>

